Workbook

Sheet SQL
B4: -- New script in 【DEV4】yzk-duel-dev4.
B5: -- Date: 2026 Apr 1
B6: -- Time: 14:26:26
B9: -- 1. eigyosyo_monthly_sales_target (営業所月次目標)
B10: SELECT
B11: cstm_cd,
B12: COUNT(*) AS record_count,
B13: MAX(insert_datetime) AS latest_insert_datetime
B14: FROM
B15: taxicloud.eigyosyo_monthly_sales_target
B16: GROUP BY
B17: cstm_cd
... B301: cstm_cd;

Sheet Sheet5
F1: =SUM(F2:F85) -> 526 | G1: =SUM(G2:G85) -> 1330568 | I1: =G1+F1 -> 1331094
B2: 1376 | C2: 1376 | D2: 150 | F2: =B2-C2 -> 0 | G2: =B2-D2 -> 1226 | O2: =SUM(O3:O13) -> 12
B3: 17811 | C3: 17741 | D3: 327 | F3: =B3-C3 -> 70 | G3: =B3-D3 -> 17484 | L3: 15 | M3: 14 | O3: =L3-M3 -> 1
B4: 1 | C4: 1 | D4: 0 | F4: =B4-C4 -> 0 | G4: =B4-D4 -> 1 | L4: 19 | M4: 18 | O4: =L4-M4 -> 1
B5: 97888 | C5: 97869 | D5: 18850 | F5: =B5-C5 -> 19 | G5: =B5-D5 -> 79038 | L5: 1 | M5: 0 | O5: =L5-M5 -> 1
B6: 65382 | C6: 65379 | D6: 13233 | F6: =B6-C6 -> 3 | G6: =B6-D6 -> 52149 | L6: 2 | M6: 1 | O6: =L6-M6 -> 1
B7: 46288 | C7: 46279 | D7: 8224 | F7: =B7-C7 -> 9 | G7: =B7-D7 -> 38064 | L7: 2 | M7: 0 | O7: =L7-M7 -> 2
B8: 54878 | C8: 54864 | D8: 19208 | F8: =B8-C8 -> 14 | G8: =B8-D8 -> 35670 | L8: 3 | M8: 2 | O8: =L8-M8 -> 1
B9: 25012 | C9: 25009 | D9: 4833 | F9: =B9-C9 -> 3 | G9: =B9-D9 -> 20179 | L9: 4 | M9: 3 | O9: =L9-M9 -> 1
B10: 5059 | C10: 5058 | D10: 1015 | F10: =B10-C10 -> 1 | G10: =B10-D10 -> 4044 | L10: 3 | M10: 2 | O10: =L10-M10 -> 1
B11: 6956 | C11: 6953 | D11: 1758 | F11: =B11-C11 -> 3 | G11: =B11-D11 -> 5198 | L11: 3 | M11: 2 | O11: =L11-M11 -> 1
B12: 2039 | C12: 2039 | D12: 570 | F12: =B12-C12 -> 0 | G12: =B12-D12 -> 1469 | L12: 1 | M12: 0 | O12: =L12-M12 -> 1
B13: 13812 | C13: 13789 | D13: 2939 | F13: =B13-C13 -> 23 | G13: =B13-D13 -> 10873 | L13: 1 | M13: 0 | O13: =L13-M13 -> 1
B14: 147632 | C14: 147606 | D14: 28523 | F14: =B14-C14 -> 26 | G14: =B14-D14 -> 119109
B15: 33694 | C15: 33682 | D15: 6309 | F15: =B15-C15 -> 12 | G15: =B15-D15 -> 27385
B16: 25715 | C16: 25709 | D16: 5803 | F16: =B16-C16 -> 6 | G16: =B16-D16 -> 19912
B17: 33213 | C17: 33204 | D17: 8896 | F17: =B17-C17 -> 9 | G17: =B17-D17 -> 24317
B18: 34973 | C18: 34968 | D18: 7251 | F18: =B18-C18 -> 5 | G18: =B18-D18 -> 27722
B19: 192 | C19: 192 | D19: 140 | F19: =B19-C19 -> 0 | G19: =B19-D19 -> 52 | O19: =SUM(O20:O32) -> 14
B20: 18058 | C20: 18053 | D20: 3257 | F20: =B20-C20 -> 5 | G20: =B20-D20 -> 14801 | K20: 8 | L20: 7 | M20: 8 | O20: =K20-L20 -> 1 | P20: =K20-M20 -> 0
B21: 27551 | C21: 27547 | D21: 5765 | F21: =B21-C21 -> 4 | G21: =B21-D21 -> 21786 | K21: 10 | L21: 9 | M21: 10 | O21: =K21-L21 -> 1 | P21: =K21-M21 -> 0
B22: 10302 | C22: 10297 | D22: 2559 | F22: =B22-C22 -> 5 | G22: =B22-D22 -> 7743 | K22: 1 | L22: 0 | M22: 1 | O22: =K22-L22 -> 1 | P22: =K22-M22 -> 0
B23: 1699 | C23: 1699 | D23: 0 | F23: =B23-C23 -> 0 | G23: =B23-D23 -> 1699 | K23: 2 | L23: 1 | M23: 2 | O23: =K23-L23 -> 1 | P23: =K23-M23 -> 0
B24: 20229 | C24: 20227 | D24: 4544 | F24: =B24-C24 -> 2 | G24: =B24-D24 -> 15685 | K24: 2 | L24: 1 | M24: 2 | O24: =K24-L24 -> 1 | P24: =K24-M24 -> 0
B25: 11112 | C25: 11111 | D25: 4291 | F25: =B25-C25 -> 1 | G25: =B25-D25 -> 6821 | K25: 1 | L25: 0 | M25: 1 | O25: =K25-L25 -> 1 | P25: =K25-M25 -> 0
B26: 14276 | C26: 14274 | D26: 3285 | F26: =B26-C26 -> 2 | G26: =B26-D26 -> 10991 | K26: 2 | L26: 0 | M26: 2 | O26: =K26-L26 -> 2 | P26: =K26-M26 -> 0
B27: 170096 | C27: 170096 | D27: 0 | F27: =B27-C27 -> 0 | G27: =B27-D27 -> 170096 | K27: 1 | L27: 0 | M27: 1 | O27: =K27-L27 -> 1 | P27: =K27-M27 -> 0
B28: 5029 | C28: 5028 | D28: 2017 | F28: =B28-C28 -> 1 | G28: =B28-D28 -> 3012 | K28: 1 | L28: 0 | M28: 1 | O28: =K28-L28 -> 1 | P28: =K28-M28 -> 0
B29: 9223 | C29: 9222 | D29: 3192 | F29: =B29-C29 -> 1 | G29: =B29-D29 -> 6031 | K29: 2 | L29: 1 | M29: 2 | O29: =K29-L29 -> 1 | P29: =K29-M29 -> 0
B30: 46318 | C30: 46309 | D30: 10196 | F30: =B30-C30 -> 9 | G30: =B30-D30 -> 36122 | K30: 1 | L30: 0 | M30: 1 | O30: =K30-L30 -> 1 | P30: =K30-M30 -> 0
B31: 371172 | C31: 371085 | D31: 88082 | F31: =B31-C31 -> 87 | G31: =B31-D31 -> 283090 | K31: 1 | L31: 0 | M31: 1 | O31: =K31-L31 -> 1 | P31: =K31-M31 -> 0
B32: 24056 | C32: 24053 | D32: 6355 | F32: =B32-C32 -> 3 | G32: =B32-D32 -> 17701 | K32: 1 | L32: 0 | M32: 1 | O32: =K32-L32 -> 1 | P32: =K32-M32 -> 0
B33: 7131 | C33: 7129 | D33: 2150 | F33: =B33-C33 -> 2 | G33: =B33-D33 -> 4981
B34: 8172 | C34: 8170 | D34: 2577 | F34: =B34-C34 -> 2 | G34: =B34-D34 -> 5595
B35: 9203 | C35: 9202 | D35: 1745 | F35: =B35-C35 -> 1 | G35: =B35-D35 -> 7458
B36: 7064 | C36: 7060 | D36: 1647 | F36: =B36-C36 -> 4 | G36: =B36-D36 -> 5417
B37: 12182 | C37: 12180 | D37: 3262 | F37: =B37-C37 -> 2 | G37: =B37-D37 -> 8920
B38: 3943 | C38: 3937 | D38: 1123 | F38: =B38-C38 -> 6 | G38: =B38-D38 -> 2820
B39: 4829 | C39: 4829 | D39: 1482 | F39: =B39-C39 -> 0 | G39: =B39-D39 -> 3347
B40: 42135 | C40: 42125 | D40: 25555 | F40: =B40-C40 -> 10 | G40: =B40-D40 -> 16580
...

Sheet 比較
T1: パッチ、および影響調査対象 | X1: duelに差分があるが、_no_alertのレコードが登録されている。リリース時に登録したものと考えられる | AB1: パッチ、および影響調査対象 | AF1: duelとblitzにはデフォルト営業所のみの連携となるため、差分が出てOK | CF1: パッチ、および影響調査対象(DUEL 売上レポートPDF出力) | CN1: パッチ、および影響調査対象 | CR1: パッチ、および影響調査対象 | CV1: パッチ、および影響調査対象（顧客「02000039」、営業所「00000002」、乗務員「000081：森岡 浩世」がduelに登録なし）
T2: 2顧客:134レコード | AB2: 3顧客:21レコード | CF2: 顧客:84,1331094 (blitz抜き)526レコード | CN2: 顧客:11,12レコード | CR2: 顧客13:14レコード | CV2: 顧客1:1レコード
A3: 調査対象 | D3: eigyosyo_monthly_sales_target | H3: eigyosyo_daily_sales_target | L3: jomuin_monthly_sales_target | P3: jomuin_daily_sales_target | T3: jomuin_mst_sales_target | X3: alert_setting | AB3: jomuin_mst_alert_setting | AF3: disposalday_mst | AJ3: client_mst | AN3: eigyokuiki_mst | AR3: eigyosyo_mst | AV3: kanrisya_mst | AZ3: kokyaku_mst | BD3: sikutyoson_mst | BH3: syaryo_mst | BL3: untentiten_mst | BP3: user_mst | BT3: userarea_l_mst | BX3: userarea_mst | CB3: userarea_p_mst | CF3: daily_pdf_tbl | CJ3: service_mst | CN3: syasyu_mst | CR3: kubun_mst | CV3: jomuin_mst
A4: ○ | B4: 顧客コード | C4: 判定 | D4: aegis件数 | E4: duel件数 | F4: blitz件数 | G4: 判定 | H4: aegis件数 | I4: duel件数 | J4: blitz件数 | K4: 判定 | L4: aegis件数 | M4: duel件数 | N4: blitz件数 | O4: 判定 | P4: aegis件数 | Q4: duel件数 | R4: blitz件数 | S4: 判定 | T4: aegis件数 | U4: duel件数 | V4: blitz件数 | W4: 判定 | X4: aegis件数 | Y4: duel件数 | Z4: blitz件数 | AA4: 判定 | AB4: aegis件数 | AC4: duel件数 | AD4: blitz件数 | AE4: 判定 | AF4: aegis件数 | AG4: duel件数 | AH4: blitz件数 | AI4: 判定 | AJ4: aegis件数 | AK4: duel件数 | AL4: blitz件数 | AM4: 判定 | AN4: aegis件数 | AO4: duel件数 | AP4: blitz件数 | AQ4: 判定 | AR4: aegis件数 | AS4: duel件数 | AT4: blitz件数 | AU4: 判定 | AV4: aegis件数 | AW4: duel件数 | AX4: blitz件数 | AY4: 判定 | AZ4: aegis件数 | BA4: duel件数 | BB4: blitz件数 | BC4: 判定 | BD4: aegis件数 | BE4: duel件数 | BF4: blitz件数 | BG4: 判定 | BH4: aegis件数 | BI4: duel件数 | BJ4: blitz件数 | BK4: 判定 | BL4: aegis件数 | BM4: duel件数 | BN4: blitz件数 | BO4: 判定 | BP4: aegis件数 | BQ4: duel件数 | BR4: blitz件数 | BS4: 判定 | BT4: aegis件数 | BU4: duel件数 | BV4: blitz件数 | BW4: 判定 | BX4: aegis件数 | BY4: duel件数 | BZ4: blitz件数 | CA4: 判定 | CB4: aegis件数 | CC4: duel件数 | CD4: blitz件数 | CE4: 判定 | CF4: aegis件数 | CG4: duel件数 | CH4: blitz件数 | CI4: 判定 | CJ4: aegis件数 | CK4: duel件数 | CL4: blitz件数 | CM4: 判定 | CN4: aegis件数 | CO4: duel件数 | CP4: blitz件数 | CQ4: 判定 | CR4: aegis件数 | CS4: duel件数 | CT4: blitz件数 | CU4: 判定 | CV4: aegis件数 | CW4: duel件数 | CX4: blitz件数 | CY4: 判定
B5: 00000001 | C5: =AND(G5,K5,O5,S5,W5,AA5,AE5,AI5,AM5,AQ5,AU5,AY5,BC5,BG5,BK5,BO5,BS5,BW5,CA5,CE5,CI5,CM5,CQ5,CU5,CY5) -> TRUE | D5: =IFERROR(VLOOKUP($B5, aegis!$B:$C, 2, FALSE), 0) -> 0 | E5: =IFERROR(VLOOKUP($B5, duel!$B:$C, 2, FALSE), 0) -> 0 | F5: =IFERROR(VLOOKUP($B5, blitz!$B:$C, 2, FALSE), 0) -> 0 | G5: =AND(D5=E5, E5=F5) -> TRUE | H5: =IFERROR(VLOOKUP($B5, aegis!$G:$H, 2, FALSE), 0) -> 0 | I5: =IFERROR(VLOOKUP($B5, duel!$G:$H, 2, FALSE), 0) -> 0 | J5: =IFERROR(VLOOKUP($B5, blitz!$G:$H, 2, FALSE), 0) -> 0 | K5: =AND(H5=I5, I5=J5) -> TRUE | L5: =IFERROR(VLOOKUP($B5, aegis!$L:$M, 2, FALSE), 0) -> 12 | M5: =IFERROR(VLOOKUP($B5, duel!$L:$M, 2, FALSE), 0) -> 12 | N5: =IFERROR(VLOOKUP($B5, blitz!$L:$M, 2, FALSE), 0) -> 12 | O5: =AND(L5=M5, M5=N5) -> TRUE | P5: =IFERROR(VLOOKUP($B5, aegis!$Q:$R, 2, FALSE), 0) -> 7 | Q5: =IFERROR(VLOOKUP($B5, duel!$Q:$R, 2, FALSE), 0) -> 7 | R5: =IFERROR(VLOOKUP($B5, blitz!$Q:$R, 2, FALSE), 0) -> 7 | S5: =AND(P5=Q5, Q5=R5) -> TRUE | T5: =IFERROR(VLOOKUP($B5, aegis!$V:$W, 2, FALSE), 0) -> 2 | U5: =IFERROR(VLOOKUP($B5, duel!$V:$W, 2, FALSE), 0) -> 2 | V5: =IFERROR(VLOOKUP($B5, blitz!$V:$W, 2, FALSE), 0) -> 2 | W5: =AND(T5=U5, U5=V5) -> TRUE | X5: =IFERROR(VLOOKUP($B5, aegis!$AA:$AB, 2, FALSE), 0) -> 1 | Y5: =IFERROR(VLOOKUP($B5, duel!$AA:$AB, 2, FALSE), 0) -> 1 | Z5: =IFERROR(VLOOKUP($B5, blitz!$AA:$AB, 2, FALSE), 0) -> 1 | AA5: =AND(X5=Y5, Y5=Z5) -> TRUE | AB5: =IFERROR(VLOOKUP($B5, aegis!$AF:$AG, 2, FALSE), 0) -> 2 | AC5: =IFERROR(VLOOKUP($B5, duel!$AF:$AG, 2, FALSE), 0) -> 2 | AD5: =IFERROR(VLOOKUP($B5, blitz!$AF:$AG, 2, FALSE), 0) -> 2 | AE5: =AND(AB5=AC5, AC5=AD5) -> TRUE | AF5: =IFERROR(VLOOKUP($B5, aegis!$AK:$AL, 2, FALSE), 0) -> 0 | AG5: =IFERROR(VLOOKUP($B5, duel!$AK:$AL, 2, FALSE), 0) -> 0 | AH5: =IFERROR(VLOOKUP($B5, blitz!$AK:$AL, 2, FALSE), 0) -> 0 | AI5: =AND(AF5=AG5, AG5=AH5) -> TRUE | AJ5: =IFERROR(VLOOKUP($B5, aegis!$AP:$AQ, 2, FALSE), 0) -> 3 | AK5: =IFERROR(VLOOKUP($B5, duel!$AP:$AQ, 2, FALSE), 0) -> 3 | AL5: =IFERROR(VLOOKUP($B5, blitz!$AP:$AQ, 2, FALSE), 0) -> 3 | AM5: =AND(AJ5=AK5, AK5=AL5) -> TRUE | AN5: =IFERROR(VLOOKUP($B5, aegis!$AU:$AV, 2, FALSE), 0) -> 3 | AO5: =IFERROR(VLOOKUP($B5, duel!$AU:$AV, 2, FALSE), 0) -> 3 | AP5: =IFERROR(VLOOKUP($B5, blitz!$AU:$AV, 2, FALSE), 0) -> 3 | AQ5: =AND(AN5=AO5, AO5=AP5) -> TRUE | AR5: =IFERROR(VLOOKUP($B5, aegis!$AZ:$BA, 2, FALSE), 0) -> 1 | AS5: =IFERROR(VLOOKUP($B5, duel!$AZ:$BA, 2, FALSE), 0) -> 1 | AT5: =IFERROR(VLOOKUP($B5, blitz!$AZ:$BA, 2, FALSE), 0) -> 1 | AU5: =AND(AR5=AS5, AS5=AT5) -> TRUE | AV5: =IFERROR(VLOOKUP($B5, aegis!$BE:$BF, 2, FALSE), 0) -> 2 | AW5: =IFERROR(VLOOKUP($B5, duel!$BE:$BF, 2, FALSE), 0) -> 2 | AX5: =IFERROR(VLOOKUP($B5, blitz!$BE:$BF, 2, FALSE), 0) -> 2 | AY5: =AND(AV5=AW5, AW5=AX5) -> TRUE | AZ5: =IFERROR(VLOOKUP($B5, aegis!$BJ:$BK, 2, FALSE), 0) -> 0 | BA5: =IFERROR(VLOOKUP($B5, duel!$BJ:$BK, 2, FALSE), 0) -> 0 | BB5: =IFERROR(VLOOKUP($B5, blitz!$BJ:$BK, 2, FALSE), 0) -> 0 | BC5: =AND(AZ5=BA5, BA5=BB5) -> TRUE | BD5: =IFERROR(VLOOKUP($B5, aegis!$BO:$BP, 2, FALSE), 0) -> 0 | BE5: =IFERROR(VLOOKUP($B5, duel!$BO:$BP, 2, FALSE), 0) -> 0 | BF5: =IFERROR(VLOOKUP($B5, blitz!$BO:$BP, 2, FALSE), 0) -> 0 | BG5: =AND(BD5=BE5, BE5=BF5) -> TRUE | BH5: =IFERROR(VLOOKUP($B5, aegis!$BT:$BU, 2, FALSE), 0) -> 0 | BI5: =IFERROR(VLOOKUP($B5, duel!$BT:$BU, 2, FALSE), 0) -> 0 | BJ5: =IFERROR(VLOOKUP($B5, blitz!$BT:$BU, 2, FALSE), 0) -> 0 | BK5: =AND(BH5=BI5, BI5=BJ5) -> TRUE | BL5: =IFERROR(VLOOKUP($B5, aegis!$BY:$BZ, 2, FALSE), 0) -> 2 | BM5: =IFERROR(VLOOKUP($B5, duel!$BY:$BZ, 2, FALSE), 0) -> 2 | BN5: =IFERROR(VLOOKUP($B5, blitz!$BY:$BZ, 2, FALSE), 0) -> 2 | BO5: =AND(BL5=BM5, BM5=BN5) -> TRUE | BP5: =IFERROR(VLOOKUP($B5, aegis!$CD:$CE, 2, FALSE), 0) -> 0 | BQ5: =IFERROR(VLOOKUP($B5, duel!$CD:$CE, 2, FALSE), 0) -> 0 | BR5: =IFERROR(VLOOKUP($B5, blitz!$CD:$CE, 2, FALSE), 0) -> 0 | BS5: =AND(BP5=BQ5, BQ5=BR5) -> TRUE | BT5: =IFERROR(VLOOKUP($B5, aegis!$CI:$CJ, 2, FALSE), 0) -> 3 | BU5: =IFERROR(VLOOKUP($B5, duel!$CI:$CJ, 2, FALSE), 0) -> 3 | BV5: =IFERROR(VLOOKUP($B5, blitz!$CI:$CJ, 2, FALSE), 0) -> 3 | BW5: =AND(BT5=BU5, BU5=BV5) -> TRUE | BX5: =IFERROR(VLOOKUP($B5, aegis!$CN:$CO, 2, FALSE), 0) -> 3 | BY5: =IFERROR(VLOOKUP($B5, duel!$CN:$CO, 2, FALSE), 0) -> 3 | BZ5: =IFERROR(VLOOKUP($B5, blitz!$CN:$CO, 2, FALSE), 0) -> 3 | CA5: =AND(BX5=BY5, BY5=BZ5) -> TRUE | CB5: =IFERROR(VLOOKUP($B5, aegis!$CS:$CT, 2, FALSE), 0) -> 14 | CC5: =IFERROR(VLOOKUP($B5, duel!$CS:$CT, 2, FALSE), 0) -> 14 | CD5: =IFERROR(VLOOKUP($B5, blitz!$CS:$CT, 2, FALSE), 0) -> 14 | CE5: =AND(CB5=CC5, CC5=CD5) -> TRUE | CF5: =IFERROR(VLOOKUP($B5, aegis!$CX:$CY, 2, FALSE), 0) -> 0 | CG5: =IFERROR(VLOOKUP($B5, duel!$CX:$CY, 2, FALSE), 0) -> 0 | CH5: =IFERROR(VLOOKUP($B5, blitz!$CX:$CY, 2, FALSE), 0) -> 0 | CI5: =AND(CF5=CG5, CG5=CH5) -> TRUE | CJ5: =IFERROR(VLOOKUP($B5, aegis!$DC:$DD, 2, FALSE), 0) -> 0 | CK5: =IFERROR(VLOOKUP($B5, duel!$DC:$DD, 2, FALSE), 0) -> 0 | CL5: =IFERROR(VLOOKUP($B5, blitz!$DC:$DD, 2, FALSE), 0) -> 0 | CM5: =AND(CJ5=CK5, CK5=CL5) -> TRUE | CN5: =IFERROR(VLOOKUP($B5, aegis!$DH:$DI, 2, FALSE), 0) -> 3 | CO5: =IFERROR(VLOOKUP($B5, duel!$DH:$DI, 2, FALSE), 0) -> 3 | CP5: =IFERROR(VLOOKUP($B5, blitz!$DH:$DI, 2, FALSE), 0) -> 0 | CQ5: =AND(CN5=CO5) -> TRUE | CR5: =IFERROR(VLOOKUP($B5, aegis!$DM:$DN, 2, FALSE), 0) -> 20 | CS5: =IFERROR(VLOOKUP($B5, duel!$DM:$DN, 2, FALSE), 0) -> 20 | CT5: =IFERROR(VLOOKUP($B5, blitz!$DM:$DN, 2, FALSE), 0) -> 20 | CU5: =AND(CR5=CS5, CS5=CT5) -> TRUE | CV5: =IFERROR(VLOOKUP($B5, aegis!$DR:$DS, 2, FALSE), 0) -> 2 | CW5: =IFERROR(VLOOKUP($B5, duel!$DR:$DS, 2, FALSE), 0) -> 2 | CX5: =IFERROR(VLOOKUP($B5, blitz!$DR:$DS, 2, FALSE), 0) -> 2 | CY5: =AND(CV5=CW5, CW5=CX5) -> TRUE
B6: 00000002 | C6: =AND(G6,K6,O6,S6,W6,AA6,AE6,AI6,AM6,AQ6,AU6,AY6,BC6,BG6,BK6,BO6,BS6,BW6,CA6,CE6,CI6,CM6,CQ6,CU6,CY6) -> TRUE | D6: =IFERROR(VLOOKUP($B6, aegis!$B:$C, 2, FALSE), 0) -> 0 | E6: =IFERROR(VLOOKUP($B6, duel!$B:$C, 2, FALSE), 0) -> 0 | F6: =IFERROR(VLOOKUP($B6, blitz!$B:$C, 2, FALSE), 0) -> 0 | G6: =AND(D6=E6, E6=F6) -> TRUE | H6: =IFERROR(VLOOKUP($B6, aegis!$G:$H, 2, FALSE), 0) -> 0 | I6: =IFERROR(VLOOKUP($B6, duel!$G:$H, 2, FALSE), 0) -> 0 | J6: =IFERROR(VLOOKUP($B6, blitz!$G:$H, 2, FALSE), 0) -> 0 | K6: =AND(H6=I6, I6=J6) -> TRUE | L6: =IFERROR(VLOOKUP($B6, aegis!$L:$M, 2, FALSE), 0) -> 12 | M6: =IFERROR(VLOOKUP($B6, duel!$L:$M, 2, FALSE), 0) -> 12 | N6: =IFERROR(VLOOKUP($B6, blitz!$L:$M, 2, FALSE), 0) -> 12 | O6: =AND(L6=M6, M6=N6) -> TRUE | P6: =IFERROR(VLOOKUP($B6, aegis!$Q:$R, 2, FALSE), 0) -> 7 | Q6: =IFERROR(VLOOKUP($B6, duel!$Q:$R, 2, FALSE), 0) -> 7 | R6: =IFERROR(VLOOKUP($B6, blitz!$Q:$R, 2, FALSE), 0) -> 7 | S6: =AND(P6=Q6, Q6=R6) -> TRUE | T6: =IFERROR(VLOOKUP($B6, aegis!$V:$W, 2, FALSE), 0) -> 0 | U6: =IFERROR(VLOOKUP($B6, duel!$V:$W, 2, FALSE), 0) -> 0 | V6: =IFERROR(VLOOKUP($B6, blitz!$V:$W, 2, FALSE), 0) -> 0 | W6: =AND(T6=U6, U6=V6) -> TRUE | X6: =IFERROR(VLOOKUP($B6, aegis!$AA:$AB, 2, FALSE), 0) -> 1 | Y6: =IFERROR(VLOOKUP($B6, duel!$AA:$AB, 2, FALSE), 0) -> 1 | Z6: =IFERROR(VLOOKUP($B6, blitz!$AA:$AB, 2, FALSE), 0) -> 1 | AA6: =AND(X6=Y6, Y6=Z6) -> TRUE | AB6: =IFERROR(VLOOKUP($B6, aegis!$AF:$AG, 2, FALSE), 0) -> 0 | AC6: =IFERROR(VLOOKUP($B6, duel!$AF:$AG, 2, FALSE), 0) -> 0 | AD6: =IFERROR(VLOOKUP($B6, blitz!$AF:$AG, 2, FALSE), 0) -> 0 | AE6: =AND(AB6=AC6, AC6=AD6) -> TRUE | AF6: =IFERROR(VLOOKUP($B6, aegis!$AK:$AL, 2, FALSE), 0) -> 0 | AG6: =IFERROR(VLOOKUP($B6, duel!$AK:$AL, 2, FALSE), 0) -> 0 | AH6: =IFERROR(VLOOKUP($B6, blitz!$AK:$AL, 2, FALSE), 0) -> 0 | AI6: =AND(AF6=AG6, AG6=AH6) -> TRUE | AJ6: =IFERROR(VLOOKUP($B6, aegis!$AP:$AQ, 2, FALSE), 0) -> 1 | AK6: =IFERROR(VLOOKUP($B6, duel!$AP:$AQ, 2, FALSE), 0) -> 1 | AL6: =IFERROR(VLOOKUP($B6, blitz!$AP:$AQ, 2, FALSE), 0) -> 1 | AM6: =AND(AJ6=AK6, AK6=AL6) -> TRUE | AN6: =IFERROR(VLOOKUP($B6, aegis!$AU:$AV, 2, FALSE), 0) -> 0 | AO6: =IFERROR(VLOOKUP($B6, duel!$AU:$AV, 2, FALSE), 0) -> 0 | AP6: =IFERROR(VLOOKUP($B6, blitz!$AU:$AV, 2, FALSE), 0) -> 0 | AQ6: =AND(AN6=AO6, AO6=AP6) -> TRUE | AR6: =IFERROR(VLOOKUP($B6, aegis!$AZ:$BA, 2, FALSE), 0) -> 1 | AS6: =IFERROR(VLOOKUP($B6, duel!$AZ:$BA, 2, FALSE), 0) -> 1 | AT6: =IFERROR(VLOOKUP($B6, blitz!$AZ:$BA, 2, FALSE), 0) -> 1 | AU6: =AND(AR6=AS6, AS6=AT6) -> TRUE | AV6: =IFERROR(VLOOKUP($B6, aegis!$BE:$BF, 2, FALSE), 0) -> 0 | AW6: =IFERROR(VLOOKUP($B6, duel!$BE:$BF, 2, FALSE), 0) -> 0 | AX6: =IFERROR(VLOOKUP($B6, blitz!$BE:$BF, 2, FALSE), 0) -> 0 | AY6: =AND(AV6=AW6, AW6=AX6) -> TRUE | AZ6: =IFERROR(VLOOKUP($B6, aegis!$BJ:$BK, 2, FALSE), 0) -> 0 | BA6: =IFERROR(VLOOKUP($B6, duel!$BJ:$BK, 2, FALSE), 0) -> 0 | BB6: =IFERROR(VLOOKUP($B6, blitz!$BJ:$BK, 2, FALSE), 0) -> 0 | BC6: =AND(AZ6=BA6, BA6=BB6) -> TRUE | BD6: =IFERROR(VLOOKUP($B6, aegis!$BO:$BP, 2, FALSE), 0) -> 0 | BE6: =IFERROR(VLOOKUP($B6, duel!$BO:$BP, 2, FALSE), 0) -> 0 | BF6: =IFERROR(VLOOKUP($B6, blitz!$BO:$BP, 2, FALSE), 0) -> 0 | BG6: =AND(BD6=BE6, BE6=BF6) -> TRUE | BH6: =IFERROR(VLOOKUP($B6, aegis!$BT:$BU, 2, FALSE), 0) -> 0 | BI6: =IFERROR(VLOOKUP($B6, duel!$BT:$BU, 2, FALSE), 0) -> 0 | BJ6: =IFERROR(VLOOKUP($B6, blitz!$BT:$BU, 2, FALSE), 0) -> 0 | BK6: =AND(BH6=BI6, BI6=BJ6) -> TRUE | BL6: =IFERROR(VLOOKUP($B6, aegis!$BY:$BZ, 2, FALSE), 0) -> 0 | BM6: =IFERROR(VLOOKUP($B6, duel!$BY:$BZ, 2, FALSE), 0) -> 0 | BN6: =IFERROR(VLOOKUP($B6, blitz!$BY:$BZ, 2, FALSE), 0) -> 0 | BO6: =AND(BL6=BM6, BM6=BN6) -> TRUE | BP6: =IFERROR(VLOOKUP($B6, aegis!$CD:$CE, 2, FALSE), 0) -> 0 | BQ6: =IFERROR(VLOOKUP($B6, duel!$CD:$CE, 2, FALSE), 0) -> 0 | BR6: =IFERROR(VLOOKUP($B6, blitz!$CD:$CE, 2, FALSE), 0) -> 0 | BS6: =AND(BP6=BQ6, BQ6=BR6) -> TRUE | BT6: =IFERROR(VLOOKUP($B6, aegis!$CI:$CJ, 2, FALSE), 0) -> 0 | BU6: =IFERROR(VLOOKUP($B6, duel!$CI:$CJ, 2, FALSE), 0) -> 0 | BV6: =IFERROR(VLOOKUP($B6, blitz!$CI:$CJ, 2, FALSE), 0) -> 0 | BW6: =AND(BT6=BU6, BU6=BV6) -> TRUE | BX6: =IFERROR(VLOOKUP($B6, aegis!$CN:$CO, 2, FALSE), 0) -> 0 | BY6: =IFERROR(VLOOKUP($B6, duel!$CN:$CO, 2, FALSE), 0) -> 0 | BZ6: =IFERROR(VLOOKUP($B6, blitz!$CN:$CO, 2, FALSE), 0) -> 0 | CA6: =AND(BX6=BY6, BY6=BZ6) -> TRUE | CB6: =IFERROR(VLOOKUP($B6, aegis!$CS:$CT, 2, FALSE), 0) -> 0 | CC6: =IFERROR(VLOOKUP($B6, duel!$CS:$CT, 2, FALSE), 0) -> 0 | CD6: =IFERROR(VLOOKUP($B6, blitz!$CS:$CT, 2, FALSE), 0) -> 0 | CE6: =AND(CB6=CC6, CC6=CD6) -> TRUE | CF6: =IFERROR(VLOOKUP($B6, aegis!$CX:$CY, 2, FALSE), 0) -> 0 | CG6: =IFERROR(VLOOKUP($B6, duel!$CX:$CY, 2, FALSE), 0) -> 0 | CH6: =IFERROR(VLOOKUP($B6, blitz!$CX:$CY, 2, FALSE), 0) -> 0 | CI6: =AND(CF6=CG6, CG6=CH6) -> TRUE | CJ6: =IFERROR(VLOOKUP($B6, aegis!$DC:$DD, 2, FALSE), 0) -> 0 | CK6: =IFERROR(VLOOKUP($B6, duel!$DC:$DD, 2, FALSE), 0) -> 0 | CL6: =IFERROR(VLOOKUP($B6, blitz!$DC:$DD, 2, FALSE), 0) -> 0 | CM6: =AND(CJ6=CK6, CK6=CL6) -> TRUE | CN6: =IFERROR(VLOOKUP($B6, aegis!$DH:$DI, 2, FALSE), 0) -> 0 | CO6: =IFERROR(VLOOKUP($B6, duel!$DH:$DI, 2, FALSE), 0) -> 0 | CP6: =IFERROR(VLOOKUP($B6, blitz!$DH:$DI, 2, FALSE), 0) -> 0 | CQ6: =AND(CN6=CO6) -> TRUE | CR6: =IFERROR(VLOOKUP($B6, aegis!$DM:$DN, 2, FALSE), 0) -> 0 | CS6: =IFERROR(VLOOKUP($B6, duel!$DM:$DN, 2, FALSE), 0) -> 0 | CT6: =IFERROR(VLOOKUP($B6, blitz!$DM:$DN, 2, FALSE), 0) -> 0 | CU6: =AND(CR6=CS6, CS6=CT6) -> TRUE | CV6: =IFERROR(VLOOKUP($B6, aegis!$DR:$DS, 2, FALSE), 0) -> 0 | CW6: =IFERROR(VLOOKUP($B6, duel!$DR:$DS, 2, FALSE), 0) -> 0 | CX6: =IFERROR(VLOOKUP($B6, blitz!$DR:$DS, 2, FALSE), 0) -> 0 | CY6: =AND(CV6=CW6, CW6=CX6) -> TRUE
B7: 00000003 | C7: =AND(G7,K7,O7,S7,W7,AA7,AE7,AI7,AM7,AQ7,AU7,AY7,BC7,BG7,BK7,BO7,BS7,BW7,CA7,CE7,CI7,CM7,CQ7,CU7,CY7) -> TRUE | D7: =IFERROR(VLOOKUP($B7, aegis!$B:$C, 2, FALSE), 0) -> 0 | E7: =IFERROR(VLOOKUP($B7, duel!$B:$C, 2, FALSE), 0) -> 0 | F7: =IFERROR(VLOOKUP($B7, blitz!$B:$C, 2, FALSE), 0) -> 0 | G7: =AND(D7=E7, E7=F7) -> TRUE | H7: =IFERROR(VLOOKUP($B7, aegis!$G:$H, 2, FALSE), 0) -> 0 | I7: =IFERROR(VLOOKUP($B7, duel!$G:$H, 2, FALSE), 0) -> 0 | J7: =IFERROR(VLOOKUP($B7, blitz!$G:$H, 2, FALSE), 0) -> 0 | K7: =AND(H7=I7, I7=J7) -> TRUE | L7: =IFERROR(VLOOKUP($B7, aegis!$L:$M, 2, FALSE), 0) -> 12 | M7: =IFERROR(VLOOKUP($B7, duel!$L:$M, 2, FALSE), 0) -> 12 | N7: =IFERROR(VLOOKUP($B7, blitz!$L:$M, 2, FALSE), 0) -> 12 | O7: =AND(L7=M7, M7=N7) -> TRUE | P7: =IFERROR(VLOOKUP($B7, aegis!$Q:$R, 2, FALSE), 0) -> 7 | Q7: =IFERROR(VLOOKUP($B7, duel!$Q:$R, 2, FALSE), 0) -> 7 | R7: =IFERROR(VLOOKUP($B7, blitz!$Q:$R, 2, FALSE), 0) -> 7 | S7: =AND(P7=Q7, Q7=R7) -> TRUE | T7: =IFERROR(VLOOKUP($B7, aegis!$V:$W, 2, FALSE), 0) -> 0 | U7: =IFERROR(VLOOKUP($B7, duel!$V:$W, 2, FALSE), 0) -> 0 | V7: =IFERROR(VLOOKUP($B7, blitz!$V:$W, 2, FALSE), 0) -> 0 | W7: =AND(T7=U7, U7=V7) -> TRUE | X7: =IFERROR(VLOOKUP($B7, aegis!$AA:$AB, 2, FALSE), 0) -> 1 | Y7: =IFERROR(VLOOKUP($B7, duel!$AA:$AB, 2, FALSE), 0) -> 1 | Z7: =IFERROR(VLOOKUP($B7, blitz!$AA:$AB, 2, FALSE), 0) -> 1 | AA7: =AND(X7=Y7, Y7=Z7) -> TRUE | AB7: =IFERROR(VLOOKUP($B7, aegis!$AF:$AG, 2, FALSE), 0) -> 0 | AC7: =IFERROR(VLOOKUP($B7, duel!$AF:$AG, 2, FALSE), 0) -> 0 | AD7: =IFERROR(VLOOKUP($B7, blitz!$AF:$AG, 2, FALSE), 0) -> 0 | AE7: =AND(AB7=AC7, AC7=AD7) -> TRUE | AF7: =IFERROR(VLOOKUP($B7, aegis!$AK:$AL, 2, FALSE), 0) -> 0 | AG7: =IFERROR(VLOOKUP($B7, duel!$AK:$AL, 2, FALSE), 0) -> 0 | AH7: =IFERROR(VLOOKUP($B7, blitz!$AK:$AL, 2, FALSE), 0) -> 0 | AI7: =AND(AF7=AG7, AG7=AH7) -> TRUE | AJ7: =IFERROR(VLOOKUP($B7, aegis!$AP:$AQ, 2, FALSE), 0) -> 1 | AK7: =IFERROR(VLOOKUP($B7, duel!$AP:$AQ, 2, FALSE), 0) -> 1 | AL7: =IFERROR(VLOOKUP($B7, blitz!$AP:$AQ, 2, FALSE), 0) -> 1 | AM7: =AND(AJ7=AK7, AK7=AL7) -> TRUE | AN7: =IFERROR(VLOOKUP($B7, aegis!$AU:$AV, 2, FALSE), 0) -> 0 | AO7: =IFERROR(VLOOKUP($B7, duel!$AU:$AV, 2, FALSE), 0) -> 0 | AP7: =IFERROR(VLOOKUP($B7, blitz!$AU:$AV, 2, FALSE), 0) -> 0 | AQ7: =AND(AN7=AO7, AO7=AP7) -> TRUE | AR7: =IFERROR(VLOOKUP($B7, aegis!$AZ:$BA, 2, FALSE), 0) -> 1 | AS7: =IFERROR(VLOOKUP($B7, duel!$AZ:$BA, 2, FALSE), 0) -> 1 | AT7: =IFERROR(VLOOKUP($B7, blitz!$AZ:$BA, 2, FALSE), 0) -> 1 | AU7: =AND(AR7=AS7, AS7=AT7) -> TRUE | AV7: =IFERROR(VLOOKUP($B7, aegis!$BE:$BF, 2, FALSE), 0) -> 0 | AW7: =IFERROR(VLOOKUP($B7, duel!$BE:$BF, 2, FALSE), 0) -> 0 | AX7: =IFERROR(VLOOKUP($B7, blitz!$BE:$BF, 2, FALSE), 0) -> 0 | AY7: =AND(AV7=AW7, AW7=AX7) -> TRUE | AZ7: =IFERROR(VLOOKUP($B7, aegis!$BJ:$BK, 2, FALSE), 0) -> 0 | BA7: =IFERROR(VLOOKUP($B7, duel!$BJ:$BK, 2, FALSE), 0) -> 0 | BB7: =IFERROR(VLOOKUP($B7, blitz!$BJ:$BK, 2, FALSE), 0) -> 0 | BC7: =AND(AZ7=BA7, BA7=BB7) -> TRUE | BD7: =IFERROR(VLOOKUP($B7, aegis!$BO:$BP, 2, FALSE), 0) -> 0 | BE7: =IFERROR(VLOOKUP($B7, duel!$BO:$BP, 2, FALSE), 0) -> 0 | BF7: =IFERROR(VLOOKUP($B7, blitz!$BO:$BP, 2, FALSE), 0) -> 0 | BG7: =AND(BD7=BE7, BE7=BF7) -> TRUE | BH7: =IFERROR(VLOOKUP($B7, aegis!$BT:$BU, 2, FALSE), 0) -> 0 | BI7: =IFERROR(VLOOKUP($B7, duel!$BT:$BU, 2, FALSE), 0) -> 0 | BJ7: =IFERROR(VLOOKUP($B7, blitz!$BT:$BU, 2, FALSE), 0) -> 0 | BK7: =AND(BH7=BI7, BI7=BJ7) -> TRUE | BL7: =IFERROR(VLOOKUP($B7, aegis!$BY:$BZ, 2, FALSE), 0) -> 0 | BM7: =IFERROR(VLOOKUP($B7, duel!$BY:$BZ, 2, FALSE), 0) -> 0 | BN7: =IFERROR(VLOOKUP($B7, blitz!$BY:$BZ, 2, FALSE), 0) -> 0 | BO7: =AND(BL7=BM7, BM7=BN7) -> TRUE | BP7: =IFERROR(VLOOKUP($B7, aegis!$CD:$CE, 2, FALSE), 0) -> 0 | BQ7: =IFERROR(VLOOKUP($B7, duel!$CD:$CE, 2, FALSE), 0) -> 0 | BR7: =IFERROR(VLOOKUP($B7, blitz!$CD:$CE, 2, FALSE), 0) -> 0 | BS7: =AND(BP7=BQ7, BQ7=BR7) -> TRUE | BT7: =IFERROR(VLOOKUP($B7, aegis!$CI:$CJ, 2, FALSE), 0) -> 0 | BU7: =IFERROR(VLOOKUP($B7, duel!$CI:$CJ, 2, FALSE), 0) -> 0 | BV7: =IFERROR(VLOOKUP($B7, blitz!$CI:$CJ, 2, FALSE), 0) -> 0 | BW7: =AND(BT7=BU7, BU7=BV7) -> TRUE | BX7: =IFERROR(VLOOKUP($B7, aegis!$CN:$CO, 2, FALSE), 0) -> 0 | BY7: =IFERROR(VLOOKUP($B7, duel!$CN:$CO, 2, FALSE), 0) -> 0 | BZ7: =IFERROR(VLOOKUP($B7, blitz!$CN:$CO, 2, FALSE), 0) -> 0 | CA7: =AND(BX7=BY7, BY7=BZ7) -> TRUE | CB7: =IFERROR(VLOOKUP($B7, aegis!$CS:$CT, 2, FALSE), 0) -> 0 | CC7: =IFERROR(VLOOKUP($B7, duel!$CS:$CT, 2, FALSE), 0) -> 0 | CD7: =IFERROR(VLOOKUP($B7, blitz!$CS:$CT, 2, FALSE), 0) -> 0 | CE7: =AND(CB7=CC7, CC7=CD7) -> TRUE | CF7: =IFERROR(VLOOKUP($B7, aegis!$CX:$CY, 2, FALSE), 0) -> 0 | CG7: =IFERROR(VLOOKUP($B7, duel!$CX:$CY, 2, FALSE), 0) -> 0 | CH7: =IFERROR(VLOOKUP($B7, blitz!$CX:$CY, 2, FALSE), 0) -> 0 | CI7: =AND(CF7=CG7, CG7=CH7) -> TRUE | CJ7: =IFERROR(VLOOKUP($B7, aegis!$DC:$DD, 2, FALSE), 0) -> 0 | CK7: =IFERROR(VLOOKUP($B7, duel!$DC:$DD, 2, FALSE), 0) -> 0 | CL7: =IFERROR(VLOOKUP($B7, blitz!$DC:$DD, 2, FALSE), 0) -> 0 | CM7: =AND(CJ7=CK7, CK7=CL7) -> TRUE | CN7: =IFERROR(VLOOKUP($B7, aegis!$DH:$DI, 2, FALSE), 0) -> 0 | CO7: =IFERROR(VLOOKUP($B7, duel!$DH:$DI, 2, FALSE), 0) -> 0 | CP7: =IFERROR(VLOOKUP($B7, blitz!$DH:$DI, 2, FALSE), 0) -> 0 | CQ7: =AND(CN7=CO7) -> TRUE | CR7: =IFERROR(VLOOKUP($B7, aegis!$DM:$DN, 2, FALSE), 0) -> 0 | CS7: =IFERROR(VLOOKUP($B7, duel!$DM:$DN, 2, FALSE), 0) -> 0 | CT7: =IFERROR(VLOOKUP($B7, blitz!$DM:$DN, 2, FALSE), 0) -> 0 | CU7: =AND(CR7=CS7, CS7=CT7) -> TRUE | CV7: =IFERROR(VLOOKUP($B7, aegis!$DR:$DS, 2, FALSE), 0) -> 0 | CW7: =IFERROR(VLOOKUP($B7, duel!$DR:$DS, 2, FALSE), 0) -> 0 | CX7: =IFERROR(VLOOKUP($B7, blitz!$DR:$DS, 2, FALSE), 0) -> 0 | CY7: =AND(CV7=CW7, CW7=CX7) -> TRUE
B8: 00000004 | C8: =AND(G8,K8,O8,S8,W8,AA8,AE8,AI8,AM8,AQ8,AU8,AY8,BC8,BG8,BK8,BO8,BS8,BW8,CA8,CE8,CI8,CM8,CQ8,CU8,CY8) -> TRUE | D8: =IFERROR(VLOOKUP($B8, aegis!$B:$C, 2, FALSE), 0) -> 0 | E8: =IFERROR(VLOOKUP($B8, duel!$B:$C, 2, FALSE), 0) -> 0 | F8: =IFERROR(VLOOKUP($B8, blitz!$B:$C, 2, FALSE), 0) -> 0 | G8: =AND(D8=E8, E8=F8) -> TRUE | H8: =IFERROR(VLOOKUP($B8, aegis!$G:$H, 2, FALSE), 0) -> 0 | I8: =IFERROR(VLOOKUP($B8, duel!$G:$H, 2, FALSE), 0) -> 0 | J8: =IFERROR(VLOOKUP($B8, blitz!$G:$H, 2, FALSE), 0) -> 0 | K8: =AND(H8=I8, I8=J8) -> TRUE | L8: =IFERROR(VLOOKUP($B8, aegis!$L:$M, 2, FALSE), 0) -> 12 | M8: =IFERROR(VLOOKUP($B8, duel!$L:$M, 2, FALSE), 0) -> 12 | N8: =IFERROR(VLOOKUP($B8, blitz!$L:$M, 2, FALSE), 0) -> 12 | O8: =AND(L8=M8, M8=N8) -> TRUE | P8: =IFERROR(VLOOKUP($B8, aegis!$Q:$R, 2, FALSE), 0) -> 7 | Q8: =IFERROR(VLOOKUP($B8, duel!$Q:$R, 2, FALSE), 0) -> 7 | R8: =IFERROR(VLOOKUP($B8, blitz!$Q:$R, 2, FALSE), 0) -> 7 | S8: =AND(P8=Q8, Q8=R8) -> TRUE | T8: =IFERROR(VLOOKUP($B8, aegis!$V:$W, 2, FALSE), 0) -> 0 | U8: =IFERROR(VLOOKUP($B8, duel!$V:$W, 2, FALSE), 0) -> 0 | V8: =IFERROR(VLOOKUP($B8, blitz!$V:$W, 2, FALSE), 0) -> 0 | W8: =AND(T8=U8, U8=V8) -> TRUE | X8: =IFERROR(VLOOKUP($B8, aegis!$AA:$AB, 2, FALSE), 0) -> 1 | Y8: =IFERROR(VLOOKUP($B8, duel!$AA:$AB, 2, FALSE), 0) -> 1 | Z8: =IFERROR(VLOOKUP($B8, blitz!$AA:$AB, 2, FALSE), 0) -> 1 | AA8: =AND(X8=Y8, Y8=Z8) -> TRUE | AB8: =IFERROR(VLOOKUP($B8, aegis!$AF:$AG, 2, FALSE), 0) -> 0 | AC8: =IFERROR(VLOOKUP($B8, duel!$AF:$AG, 2, FALSE), 0) -> 0 | AD8: =IFERROR(VLOOKUP($B8, blitz!$AF:$AG, 2, FALSE), 0) -> 0 | AE8: =AND(AB8=AC8, AC8=AD8) -> TRUE | AF8: =IFERROR(VLOOKUP($B8, aegis!$AK:$AL, 2, FALSE), 0) -> 0 | AG8: =IFERROR(VLOOKUP($B8, duel!$AK:$AL, 2, FALSE), 0) -> 0 | AH8: =IFERROR(VLOOKUP($B8, blitz!$AK:$AL, 2, FALSE), 0) -> 0 | AI8: =AND(AF8=AG8, AG8=AH8) -> TRUE | AJ8: =IFERROR(VLOOKUP($B8, aegis!$AP:$AQ, 2, FALSE), 0) -> 1 | AK8: =IFERROR(VLOOKUP($B8, duel!$AP:$AQ, 2, FALSE), 0) -> 1 | AL8: =IFERROR(VLOOKUP($B8, blitz!$AP:$AQ, 2, FALSE), 0) -> 1 | AM8: =AND(AJ8=AK8, AK8=AL8) -> TRUE | AN8: =IFERROR(VLOOKUP($B8, aegis!$AU:$AV, 2, FALSE), 0) -> 0 | AO8: =IFERROR(VLOOKUP($B8, duel!$AU:$AV, 2, FALSE), 0) -> 0 | AP8: =IFERROR(VLOOKUP($B8, blitz!$AU:$AV, 2, FALSE), 0) -> 0 | AQ8: =AND(AN8=AO8, AO8=AP8) -> TRUE | AR8: =IFERROR(VLOOKUP($B8, aegis!$AZ:$BA, 2, FALSE), 0) -> 1 | AS8: =IFERROR(VLOOKUP($B8, duel!$AZ:$BA, 2, FALSE), 0) -> 1 | AT8: =IFERROR(VLOOKUP($B8, blitz!$AZ:$BA, 2, FALSE), 0) -> 1 | AU8: =AND(AR8=AS8, AS8=AT8) -> TRUE | AV8: =IFERROR(VLOOKUP($B8, aegis!$BE:$BF, 2, FALSE), 0) -> 0 | AW8: =IFERROR(VLOOKUP($B8, duel!$BE:$BF, 2, FALSE), 0) -> 0 | AX8: =IFERROR(VLOOKUP($B8, blitz!$BE:$BF, 2, FALSE), 0) -> 0 | AY8: =AND(AV8=AW8, AW8=AX8) -> TRUE | AZ8: =IFERROR(VLOOKUP($B8, aegis!$BJ:$BK, 2, FALSE), 0) -> 0 | BA8: =IFERROR(VLOOKUP($B8, duel!$BJ:$BK, 2, FALSE), 0) -> 0 | BB8: =IFERROR(VLOOKUP($B8, blitz!$BJ:$BK, 2, FALSE), 0) -> 0 | BC8: =AND(AZ8=BA8, BA8=BB8) -> TRUE | BD8: =IFERROR(VLOOKUP($B8, aegis!$BO:$BP, 2, FALSE), 0) -> 0 | BE8: =IFERROR(VLOOKUP($B8, duel!$BO:$BP, 2, FALSE), 0) -> 0 | BF8: =IFERROR(VLOOKUP($B8, blitz!$BO:$BP, 2, FALSE), 0) -> 0 | BG8: =AND(BD8=BE8, BE8=BF8) -> TRUE | BH8: =IFERROR(VLOOKUP($B8, aegis!$BT:$BU, 2, FALSE), 0) -> 0 | BI8: =IFERROR(VLOOKUP($B8, duel!$BT:$BU, 2, FALSE), 0) -> 0 | BJ8: =IFERROR(VLOOKUP($B8, blitz!$BT:$BU, 2, FALSE), 0) -> 0 | BK8: =AND(BH8=BI8, BI8=BJ8) -> TRUE | BL8: =IFERROR(VLOOKUP($B8, aegis!$BY:$BZ, 2, FALSE), 0) -> 0 | BM8: =IFERROR(VLOOKUP($B8, duel!$BY:$BZ, 2, FALSE), 0) -> 0 | BN8: =IFERROR(VLOOKUP($B8, blitz!$BY:$BZ, 2, FALSE), 0) -> 0 | BO8: =AND(BL8=BM8, BM8=BN8) -> TRUE | BP8: =IFERROR(VLOOKUP($B8, aegis!$CD:$CE, 2, FALSE), 0) -> 0 | BQ8: =IFERROR(VLOOKUP($B8, duel!$CD:$CE, 2, FALSE), 0) -> 0 | BR8: =IFERROR(VLOOKUP($B8, blitz!$CD:$CE, 2, FALSE), 0) -> 0 | BS8: =AND(BP8=BQ8, BQ8=BR8) -> TRUE | BT8: =IFERROR(VLOOKUP($B8, aegis!$CI:$CJ, 2, FALSE), 0) -> 0 | BU8: =IFERROR(VLOOKUP($B8, duel!$CI:$CJ, 2, FALSE), 0) -> 0 | BV8: =IFERROR(VLOOKUP($B8, blitz!$CI:$CJ, 2, FALSE), 0) -> 0 | BW8: =AND(BT8=BU8, BU8=BV8) -> TRUE | BX8: =IFERROR(VLOOKUP($B8, aegis!$CN:$CO, 2, FALSE), 0) -> 0 | BY8: =IFERROR(VLOOKUP($B8, duel!$CN:$CO, 2, FALSE), 0) -> 0 | BZ8: =IFERROR(VLOOKUP($B8, blitz!$CN:$CO, 2, FALSE), 0) -> 0 | CA8: =AND(BX8=BY8, BY8=BZ8) -> TRUE | CB8: =IFERROR(VLOOKUP($B8, aegis!$CS:$CT, 2, FALSE), 0) -> 0 | CC8: =IFERROR(VLOOKUP($B8, duel!$CS:$CT, 2, FALSE), 0) -> 0 | CD8: =IFERROR(VLOOKUP($B8, blitz!$CS:$CT, 2, FALSE), 0) -> 0 | CE8: =AND(CB8=CC8, CC8=CD8) -> TRUE | CF8: =IFERROR(VLOOKUP($B8, aegis!$CX:$CY, 2, FALSE), 0) -> 0 | CG8: =IFERROR(VLOOKUP($B8, duel!$CX:$CY, 2, FALSE), 0) -> 0 | CH8: =IFERROR(VLOOKUP($B8, blitz!$CX:$CY, 2, FALSE), 0) -> 0 | CI8: =AND(CF8=CG8, CG8=CH8) -> TRUE | CJ8: =IFERROR(VLOOKUP($B8, aegis!$DC:$DD, 2, FALSE), 0) -> 0 | CK8: =IFERROR(VLOOKUP($B8, duel!$DC:$DD, 2, FALSE), 0) -> 0 | CL8: =IFERROR(VLOOKUP($B8, blitz!$DC:$DD, 2, FALSE), 0) -> 0 | CM8: =AND(CJ8=CK8, CK8=CL8) -> TRUE | CN8: =IFERROR(VLOOKUP($B8, aegis!$DH:$DI, 2, FALSE), 0) -> 0 | CO8: =IFERROR(VLOOKUP($B8, duel!$DH:$DI, 2, FALSE), 0) -> 0 | CP8: =IFERROR(VLOOKUP($B8, blitz!$DH:$DI, 2, FALSE), 0) -> 0 | CQ8: =AND(CN8=CO8) -> TRUE | CR8: =IFERROR(VLOOKUP($B8, aegis!$DM:$DN, 2, FALSE), 0) -> 0 | CS8: =IFERROR(VLOOKUP($B8, duel!$DM:$DN, 2, FALSE), 0) -> 0 | CT8: =IFERROR(VLOOKUP($B8, blitz!$DM:$DN, 2, FALSE), 0) -> 0 | CU8: =AND(CR8=CS8, CS8=CT8) -> TRUE | CV8: =IFERROR(VLOOKUP($B8, aegis!$DR:$DS, 2, FALSE), 0) -> 0 | CW8: =IFERROR(VLOOKUP($B8, duel!$DR:$DS, 2, FALSE), 0) -> 0 | CX8: =IFERROR(VLOOKUP($B8, blitz!$DR:$DS, 2, FALSE), 0) -> 0 | CY8: =AND(CV8=CW8, CW8=CX8) -> TRUE
B9: 00000005 | C9: =AND(G9,K9,O9,S9,W9,AA9,AE9,AI9,AM9,AQ9,AU9,AY9,BC9,BG9,BK9,BO9,BS9,BW9,CA9,CE9,CI9,CM9,CQ9,CU9,CY9) -> TRUE | D9: =IFERROR(VLOOKUP($B9, aegis!$B:$C, 2, FALSE), 0) -> 0 | E9: =IFERROR(VLOOKUP($B9, duel!$B:$C, 2, FALSE), 0) -> 0 | F9: =IFERROR(VLOOKUP($B9, blitz!$B:$C, 2, FALSE), 0) -> 0 | G9: =AND(D9=E9, E9=F9) -> TRUE | H9: =IFERROR(VLOOKUP($B9, aegis!$G:$H, 2, FALSE), 0) -> 0 | I9: =IFERROR(VLOOKUP($B9, duel!$G:$H, 2, FALSE), 0) -> 0 | J9: =IFERROR(VLOOKUP($B9, blitz!$G:$H, 2, FALSE), 0) -> 0 | K9: =AND(H9=I9, I9=J9) -> TRUE | L9: =IFERROR(VLOOKUP($B9, aegis!$L:$M, 2, FALSE), 0) -> 12 | M9: =IFERROR(VLOOKUP($B9, duel!$L:$M, 2, FALSE), 0) -> 12 | N9: =IFERROR(VLOOKUP($B9, blitz!$L:$M, 2, FALSE), 0) -> 12 | O9: =AND(L9=M9, M9=N9) -> TRUE | P9: =IFERROR(VLOOKUP($B9, aegis!$Q:$R, 2, FALSE), 0) -> 7 | Q9: =IFERROR(VLOOKUP($B9, duel!$Q:$R, 2, FALSE), 0) -> 7 | R9: =IFERROR(VLOOKUP($B9, blitz!$Q:$R, 2, FALSE), 0) -> 7 | S9: =AND(P9=Q9, Q9=R9) -> TRUE | T9: =IFERROR(VLOOKUP($B9, aegis!$V:$W, 2, FALSE), 0) -> 0 | U9: =IFERROR(VLOOKUP($B9, duel!$V:$W, 2, FALSE), 0) -> 0 | V9: =IFERROR(VLOOKUP($B9, blitz!$V:$W, 2, FALSE), 0) -> 0 | W9: =AND(T9=U9, U9=V9) -> TRUE | X9: =IFERROR(VLOOKUP($B9, aegis!$AA:$AB, 2, FALSE), 0) -> 1 | Y9: =IFERROR(VLOOKUP($B9, duel!$AA:$AB, 2, FALSE), 0) -> 1 | Z9: =IFERROR(VLOOKUP($B9, blitz!$AA:$AB, 2, FALSE), 0) -> 1 | AA9: =AND(X9=Y9, Y9=Z9) -> TRUE | AB9: =IFERROR(VLOOKUP($B9, aegis!$AF:$AG, 2, FALSE), 0) -> 0 | AC9: =IFERROR(VLOOKUP($B9, duel!$AF:$AG, 2, FALSE), 0) -> 0 | AD9: =IFERROR(VLOOKUP($B9, blitz!$AF:$AG, 2, FALSE), 0) -> 0 | AE9: =AND(AB9=AC9, AC9=AD9) -> TRUE | AF9: =IFERROR(VLOOKUP($B9, aegis!$AK:$AL, 2, FALSE), 0) -> 0 | AG9: =IFERROR(VLOOKUP($B9, duel!$AK:$AL, 2, FALSE), 0) -> 0 | AH9: =IFERROR(VLOOKUP($B9, blitz!$AK:$AL, 2, FALSE), 0) -> 0 | AI9: =AND(AF9=AG9, AG9=AH9) -> TRUE | AJ9: =IFERROR(VLOOKUP($B9, aegis!$AP:$AQ, 2, FALSE), 0) -> 1 | AK9: =IFERROR(VLOOKUP($B9, duel!$AP:$AQ, 2, FALSE), 0) -> 1 | AL9: =IFERROR(VLOOKUP($B9, blitz!$AP:$AQ, 2, FALSE), 0) -> 1 | AM9: =AND(AJ9=AK9, AK9=AL9) -> TRUE | AN9: =IFERROR(VLOOKUP($B9, aegis!$AU:$AV, 2, FALSE), 0) -> 0 | AO9: =IFERROR(VLOOKUP($B9, duel!$AU:$AV, 2, FALSE), 0) -> 0 | AP9: =IFERROR(VLOOKUP($B9, blitz!$AU:$AV, 2, FALSE), 0) -> 0 | AQ9: =AND(AN9=AO9, AO9=AP9) -> TRUE | AR9: =IFERROR(VLOOKUP($B9, aegis!$AZ:$BA, 2, FALSE), 0) -> 1 | AS9: =IFERROR(VLOOKUP($B9, duel!$AZ:$BA, 2, FALSE), 0) -> 1 | AT9: =IFERROR(VLOOKUP($B9, blitz!$AZ:$BA, 2, FALSE), 0) -> 1 | AU9: =AND(AR9=AS9, AS9=AT9) -> TRUE | AV9: =IFERROR(VLOOKUP($B9, aegis!$BE:$BF, 2, FALSE), 0) -> 0 | AW9: =IFERROR(VLOOKUP($B9, duel!$BE:$BF, 2, FALSE), 0) -> 0 | AX9: =IFERROR(VLOOKUP($B9, blitz!$BE:$BF, 2, FALSE), 0) -> 0 | AY9: =AND(AV9=AW9, AW9=AX9) -> TRUE | AZ9: =IFERROR(VLOOKUP($B9, aegis!$BJ:$BK, 2, FALSE), 0) -> 0 | BA9: =IFERROR(VLOOKUP($B9, duel!$BJ:$BK, 2, FALSE), 0) -> 0 | BB9: =IFERROR(VLOOKUP($B9, blitz!$BJ:$BK, 2, FALSE), 0) -> 0 | BC9: =AND(AZ9=BA9, BA9=BB9) -> TRUE | BD9: =IFERROR(VLOOKUP($B9, aegis!$BO:$BP, 2, FALSE), 0) -> 0 | BE9: =IFERROR(VLOOKUP($B9, duel!$BO:$BP, 2, FALSE), 0) -> 0 | BF9: =IFERROR(VLOOKUP($B9, blitz!$BO:$BP, 2, FALSE), 0) -> 0 | BG9: =AND(BD9=BE9, BE9=BF9) -> TRUE | BH9: =IFERROR(VLOOKUP($B9, aegis!$BT:$BU, 2, FALSE), 0) -> 0 | BI9: =IFERROR(VLOOKUP($B9, duel!$BT:$BU, 2, FALSE), 0) -> 0 | BJ9: =IFERROR(VLOOKUP($B9, blitz!$BT:$BU, 2, FALSE), 0) -> 0 | BK9: =AND(BH9=BI9, BI9=BJ9) -> TRUE | BL9: =IFERROR(VLOOKUP($B9, aegis!$BY:$BZ, 2, FALSE), 0) -> 0 | BM9: =IFERROR(VLOOKUP($B9, duel!$BY:$BZ, 2, FALSE), 0) -> 0 | BN9: =IFERROR(VLOOKUP($B9, blitz!$BY:$BZ, 2, FALSE), 0) -> 0 | BO9: =AND(BL9=BM9, BM9=BN9) -> TRUE | BP9: =IFERROR(VLOOKUP($B9, aegis!$CD:$CE, 2, FALSE), 0) -> 0 | BQ9: =IFERROR(VLOOKUP($B9, duel!$CD:$CE, 2, FALSE), 0) -> 0 | BR9: =IFERROR(VLOOKUP($B9, blitz!$CD:$CE, 2, FALSE), 0) -> 0 | BS9: =AND(BP9=BQ9, BQ9=BR9) -> TRUE | BT9: =IFERROR(VLOOKUP($B9, aegis!$CI:$CJ, 2, FALSE), 0) -> 0 | BU9: =IFERROR(VLOOKUP($B9, duel!$CI:$CJ, 2, FALSE), 0) -> 0 | BV9: =IFERROR(VLOOKUP($B9, blitz!$CI:$CJ, 2, FALSE), 0) -> 0 | BW9: =AND(BT9=BU9, BU9=BV9) -> TRUE | BX9: =IFERROR(VLOOKUP($B9, aegis!$CN:$CO, 2, FALSE), 0) -> 0 | BY9: =IFERROR(VLOOKUP($B9, duel!$CN:$CO, 2, FALSE), 0) -> 0 | BZ9: =IFERROR(VLOOKUP($B9, blitz!$CN:$CO, 2, FALSE), 0) -> 0 | CA9: =AND(BX9=BY9, BY9=BZ9) -> TRUE | CB9: =IFERROR(VLOOKUP($B9, aegis!$CS:$CT, 2, FALSE), 0) -> 0 | CC9: =IFERROR(VLOOKUP($B9, duel!$CS:$CT, 2, FALSE), 0) -> 0 | CD9: =IFERROR(VLOOKUP($B9, blitz!$CS:$CT, 2, FALSE), 0) -> 0 | CE9: =AND(CB9=CC9, CC9=CD9) -> TRUE | CF9: =IFERROR(VLOOKUP($B9, aegis!$CX:$CY, 2, FALSE), 0) -> 0 | CG9: =IFERROR(VLOOKUP($B9, duel!$CX:$CY, 2, FALSE), 0) -> 0 | CH9: =IFERROR(VLOOKUP($B9, blitz!$CX:$CY, 2, FALSE), 0) -> 0 | CI9: =AND(CF9=CG9, CG9=CH9) -> TRUE | CJ9: =IFERROR(VLOOKUP($B9, aegis!$DC:$DD, 2, FALSE), 0) -> 0 | CK9: =IFERROR(VLOOKUP($B9, duel!$DC:$DD, 2, FALSE), 0) -> 0 | CL9: =IFERROR(VLOOKUP($B9, blitz!$DC:$DD, 2, FALSE), 0) -> 0 | CM9: =AND(CJ9=CK9, CK9=CL9) -> TRUE | CN9: =IFERROR(VLOOKUP($B9, aegis!$DH:$DI, 2, FALSE), 0) -> 0 | CO9: =IFERROR(VLOOKUP($B9, duel!$DH:$DI, 2, FALSE), 0) -> 0 | CP9: =IFERROR(VLOOKUP($B9, blitz!$DH:$DI, 2, FALSE), 0) -> 0 | CQ9: =AND(CN9=CO9) -> TRUE | CR9: =IFERROR(VLOOKUP($B9, aegis!$DM:$DN, 2, FALSE), 0) -> 0 | CS9: =IFERROR(VLOOKUP($B9, duel!$DM:$DN, 2, FALSE), 0) -> 0 | CT9: =IFERROR(VLOOKUP($B9, blitz!$DM:$DN, 2, FALSE), 0) -> 0 | CU9: =AND(CR9=CS9, CS9=CT9) -> TRUE | CV9: =IFERROR(VLOOKUP($B9, aegis!$DR:$DS, 2, FALSE), 0) -> 0 | CW9: =IFERROR(VLOOKUP($B9, duel!$DR:$DS, 2, FALSE), 0) -> 0 | CX9: =IFERROR(VLOOKUP($B9, blitz!$DR:$DS, 2, FALSE), 0) -> 0 | CY9: =AND(CV9=CW9, CW9=CX9) -> TRUE
B10: 00000007 | C10: =AND(G10,K10,O10,S10,W10,AA10,AE10,AI10,AM10,AQ10,AU10,AY10,BC10,BG10,BK10,BO10,BS10,BW10,CA10,CE10,CI10,CM10,CQ10,CU10,CY10) -> TRUE | D10: =IFERROR(VLOOKUP($B10, aegis!$B:$C, 2, FALSE), 0) -> 0 | E10: =IFERROR(VLOOKUP($B10, duel!$B:$C, 2, FALSE), 0) -> 0 | F10: =IFERROR(VLOOKUP($B10, blitz!$B:$C, 2, FALSE), 0) -> 0 | G10: =AND(D10=E10, E10=F10) -> TRUE | H10: =IFERROR(VLOOKUP($B10, aegis!$G:$H, 2, FALSE), 0) -> 0 | I10: =IFERROR(VLOOKUP($B10, duel!$G:$H, 2, FALSE), 0) -> 0 | J10: =IFERROR(VLOOKUP($B10, blitz!$G:$H, 2, FALSE), 0) -> 0 | K10: =AND(H10=I10, I10=J10) -> TRUE | L10: =IFERROR(VLOOKUP($B10, aegis!$L:$M, 2, FALSE), 0) -> 12 | M10: =IFERROR(VLOOKUP($B10, duel!$L:$M, 2, FALSE), 0) -> 12 | N10: =IFERROR(VLOOKUP($B10, blitz!$L:$M, 2, FALSE), 0) -> 12 | O10: =AND(L10=M10, M10=N10) -> TRUE | P10: =IFERROR(VLOOKUP($B10, aegis!$Q:$R, 2, FALSE), 0) -> 7 | Q10: =IFERROR(VLOOKUP($B10, duel!$Q:$R, 2, FALSE), 0) -> 7 | R10: =IFERROR(VLOOKUP($B10, blitz!$Q:$R, 2, FALSE), 0) -> 7 | S10: =AND(P10=Q10, Q10=R10) -> TRUE | T10: =IFERROR(VLOOKUP($B10, aegis!$V:$W, 2, FALSE), 0) -> 0 | U10: =IFERROR(VLOOKUP($B10, duel!$V:$W, 2, FALSE), 0) -> 0 | V10: =IFERROR(VLOOKUP($B10, blitz!$V:$W, 2, FALSE), 0) -> 0 | W10: =AND(T10=U10, U10=V10) -> TRUE | X10: =IFERROR(VLOOKUP($B10, aegis!$AA:$AB, 2, FALSE), 0) -> 1 | Y10: =IFERROR(VLOOKUP($B10, duel!$AA:$AB, 2, FALSE), 0) -> 1 | Z10: =IFERROR(VLOOKUP($B10, blitz!$AA:$AB, 2, FALSE), 0) -> 1 | AA10: =AND(X10=Y10, Y10=Z10) -> TRUE | AB10: =IFERROR(VLOOKUP($B10, aegis!$AF:$AG, 2, FALSE), 0) -> 0 | AC10: =IFERROR(VLOOKUP($B10, duel!$AF:$AG, 2, FALSE), 0) -> 0 | AD10: =IFERROR(VLOOKUP($B10, blitz!$AF:$AG, 2, FALSE), 0) -> 0 | AE10: =AND(AB10=AC10, AC10=AD10) -> TRUE | AF10: =IFERROR(VLOOKUP($B10, aegis!$AK:$AL, 2, FALSE), 0) -> 0 | AG10: =IFERROR(VLOOKUP($B10, duel!$AK:$AL, 2, FALSE), 0) -> 0 | AH10: =IFERROR(VLOOKUP($B10, blitz!$AK:$AL, 2, FALSE), 0) -> 0 | AI10: =AND(AF10=AG10, AG10=AH10) -> TRUE | AJ10: =IFERROR(VLOOKUP($B10, aegis!$AP:$AQ, 2, FALSE), 0) -> 1 | AK10: =IFERROR(VLOOKUP($B10, duel!$AP:$AQ, 2, FALSE), 0) -> 1 | AL10: =IFERROR(VLOOKUP($B10, blitz!$AP:$AQ, 2, FALSE), 0) -> 1 | AM10: =AND(AJ10=AK10, AK10=AL10) -> TRUE | AN10: =IFERROR(VLOOKUP($B10, aegis!$AU:$AV, 2, FALSE), 0) -> 0 | AO10: =IFERROR(VLOOKUP($B10, duel!$AU:$AV, 2, FALSE), 0) -> 0 | AP10: =IFERROR(VLOOKUP($B10, blitz!$AU:$AV, 2, FALSE), 0) -> 0 | AQ10: =AND(AN10=AO10, AO10=AP10) -> TRUE | AR10: =IFERROR(VLOOKUP($B10, aegis!$AZ:$BA, 2, FALSE), 0) -> 1 | AS10: =IFERROR(VLOOKUP($B10, duel!$AZ:$BA, 2, FALSE), 0) -> 1 | AT10: =IFERROR(VLOOKUP($B10, blitz!$AZ:$BA, 2, FALSE), 0) -> 1 | AU10: =AND(AR10=AS10, AS10=AT10) -> TRUE | AV10: =IFERROR(VLOOKUP($B10, aegis!$BE:$BF, 2, FALSE), 0) -> 0 | AW10: =IFERROR(VLOOKUP($B10, duel!$BE:$BF, 2, FALSE), 0) -> 0 | AX10: =IFERROR(VLOOKUP($B10, blitz!$BE:$BF, 2, FALSE), 0) -> 0 | AY10: =AND(AV10=AW10, AW10=AX10) -> TRUE | AZ10: =IFERROR(VLOOKUP($B10, aegis!$BJ:$BK, 2, FALSE), 0) -> 0 | BA10: =IFERROR(VLOOKUP($B10, duel!$BJ:$BK, 2, FALSE), 0) -> 0 | BB10: =IFERROR(VLOOKUP($B10, blitz!$BJ:$BK, 2, FALSE), 0) -> 0 | BC10: =AND(AZ10=BA10, BA10=BB10) -> TRUE | BD10: =IFERROR(VLOOKUP($B10, aegis!$BO:$BP, 2, FALSE), 0) -> 0 | BE10: =IFERROR(VLOOKUP($B10, duel!$BO:$BP, 2, FALSE), 0) -> 0 | BF10: =IFERROR(VLOOKUP($B10, blitz!$BO:$BP, 2, FALSE), 0) -> 0 | BG10: =AND(BD10=BE10, BE10=BF10) -> TRUE | BH10: =IFERROR(VLOOKUP($B10, aegis!$BT:$BU, 2, FALSE), 0) -> 0 | BI10: =IFERROR(VLOOKUP($B10, duel!$BT:$BU, 2, FALSE), 0) -> 0 | BJ10: =IFERROR(VLOOKUP($B10, blitz!$BT:$BU, 2, FALSE), 0) -> 0 | BK10: =AND(BH10=BI10, BI10=BJ10) -> TRUE | BL10: =IFERROR(VLOOKUP($B10, aegis!$BY:$BZ, 2, FALSE), 0) -> 0 | BM10: =IFERROR(VLOOKUP($B10, duel!$BY:$BZ, 2, FALSE), 0) -> 0 | BN10: =IFERROR(VLOOKUP($B10, blitz!$BY:$BZ, 2, FALSE), 0) -> 0 | BO10: =AND(BL10=BM10, BM10=BN10) -> TRUE | BP10: =IFERROR(VLOOKUP($B10, aegis!$CD:$CE, 2, FALSE), 0) -> 0 | BQ10: =IFERROR(VLOOKUP($B10, duel!$CD:$CE, 2, FALSE), 0) -> 0 | BR10: =IFERROR(VLOOKUP($B10, blitz!$CD:$CE, 2, FALSE), 0) -> 0 | BS10: =AND(BP10=BQ10, BQ10=BR10) -> TRUE | BT10: =IFERROR(VLOOKUP($B10, aegis!$CI:$CJ, 2, FALSE), 0) -> 0 | BU10: =IFERROR(VLOOKUP($B10, duel!$CI:$CJ, 2, FALSE), 0) -> 0 | BV10: =IFERROR(VLOOKUP($B10, blitz!$CI:$CJ, 2, FALSE), 0) -> 0 | BW10: =AND(BT10=BU10, BU10=BV10) -> TRUE | BX10: =IFERROR(VLOOKUP($B10, aegis!$CN:$CO, 2, FALSE), 0) -> 0 | BY10: =IFERROR(VLOOKUP($B10, duel!$CN:$CO, 2, FALSE), 0) -> 0 | BZ10: =IFERROR(VLOOKUP($B10, blitz!$CN:$CO, 2, FALSE), 0) -> 0 | CA10: =AND(BX10=BY10, BY10=BZ10) -> TRUE | CB10: =IFERROR(VLOOKUP($B10, aegis!$CS:$CT, 2, FALSE), 0) -> 0 | CC10: =IFERROR(VLOOKUP($B10, duel!$CS:$CT, 2, FALSE), 0) -> 0 | CD10: =IFERROR(VLOOKUP($B10, blitz!$CS:$CT, 2, FALSE), 0) -> 0 | CE10: =AND(CB10=CC10, CC10=CD10) -> TRUE | CF10: =IFERROR(VLOOKUP($B10, aegis!$CX:$CY, 2, FALSE), 0) -> 0 | CG10: =IFERROR(VLOOKUP($B10, duel!$CX:$CY, 2, FALSE), 0) -> 0 | CH10: =IFERROR(VLOOKUP($B10, blitz!$CX:$CY, 2, FALSE), 0) -> 0 | CI10: =AND(CF10=CG10, CG10=CH10) -> TRUE | CJ10: =IFERROR(VLOOKUP($B10, aegis!$DC:$DD, 2, FALSE), 0) -> 0 | CK10: =IFERROR(VLOOKUP($B10, duel!$DC:$DD, 2, FALSE), 0) -> 0 | CL10: =IFERROR(VLOOKUP($B10, blitz!$DC:$DD, 2, FALSE), 0) -> 0 | CM10: =AND(CJ10=CK10, CK10=CL10) -> TRUE | CN10: =IFERROR(VLOOKUP($B10, aegis!$DH:$DI, 2, FALSE), 0) -> 0 | CO10: =IFERROR(VLOOKUP($B10, duel!$DH:$DI, 2, FALSE), 0) -> 0 | CP10: =IFERROR(VLOOKUP($B10, blitz!$DH:$DI, 2, FALSE), 0) -> 0 | CQ10: =AND(CN10=CO10) -> TRUE | CR10: =IFERROR(VLOOKUP($B10, aegis!$DM:$DN, 2, FALSE), 0) -> 0 | CS10: =IFERROR(VLOOKUP($B10, duel!$DM:$DN, 2, FALSE), 0) -> 0 | CT10: =IFERROR(VLOOKUP($B10, blitz!$DM:$DN, 2, FALSE), 0) -> 0 | CU10: =AND(CR10=CS10, CS10=CT10) -> TRUE | CV10: =IFERROR(VLOOKUP($B10, aegis!$DR:$DS, 2, FALSE), 0) -> 0 | CW10: =IFERROR(VLOOKUP($B10, duel!$DR:$DS, 2, FALSE), 0) -> 0 | CX10: =IFERROR(VLOOKUP($B10, blitz!$DR:$DS, 2, FALSE), 0) -> 0 | CY10: =AND(CV10=CW10, CW10=CX10) -> TRUE
B11: 00000008 | C11: =AND(G11,K11,O11,S11,W11,AA11,AE11,AI11,AM11,AQ11,AU11,AY11,BC11,BG11,BK11,BO11,BS11,BW11,CA11,CE11,CI11,CM11,CQ11,CU11,CY11) -> TRUE | D11: =IFERROR(VLOOKUP($B11, aegis!$B:$C, 2, FALSE), 0) -> 0 | E11: =IFERROR(VLOOKUP($B11, duel!$B:$C, 2, FALSE), 0) -> 0 | F11: =IFERROR(VLOOKUP($B11, blitz!$B:$C, 2, FALSE), 0) -> 0 | G11: =AND(D11=E11, E11=F11) -> TRUE | H11: =IFERROR(VLOOKUP($B11, aegis!$G:$H, 2, FALSE), 0) -> 0 | I11: =IFERROR(VLOOKUP($B11, duel!$G:$H, 2, FALSE), 0) -> 0 | J11: =IFERROR(VLOOKUP($B11, blitz!$G:$H, 2, FALSE), 0) -> 0 | K11: =AND(H11=I11, I11=J11) -> TRUE | L11: =IFERROR(VLOOKUP($B11, aegis!$L:$M, 2, FALSE), 0) -> 12 | M11: =IFERROR(VLOOKUP($B11, duel!$L:$M, 2, FALSE), 0) -> 12 | N11: =IFERROR(VLOOKUP($B11, blitz!$L:$M, 2, FALSE), 0) -> 12 | O11: =AND(L11=M11, M11=N11) -> TRUE | P11: =IFERROR(VLOOKUP($B11, aegis!$Q:$R, 2, FALSE), 0) -> 7 | Q11: =IFERROR(VLOOKUP($B11, duel!$Q:$R, 2, FALSE), 0) -> 7 | R11: =IFERROR(VLOOKUP($B11, blitz!$Q:$R, 2, FALSE), 0) -> 7 | S11: =AND(P11=Q11, Q11=R11) -> TRUE | T11: =IFERROR(VLOOKUP($B11, aegis!$V:$W, 2, FALSE), 0) -> 0 | U11: =IFERROR(VLOOKUP($B11, duel!$V:$W, 2, FALSE), 0) -> 0 | V11: =IFERROR(VLOOKUP($B11, blitz!$V:$W, 2, FALSE), 0) -> 0 | W11: =AND(T11=U11, U11=V11) -> TRUE | X11: =IFERROR(VLOOKUP($B11, aegis!$AA:$AB, 2, FALSE), 0) -> 1 | Y11: =IFERROR(VLOOKUP($B11, duel!$AA:$AB, 2, FALSE), 0) -> 1 | Z11: =IFERROR(VLOOKUP($B11, blitz!$AA:$AB, 2, FALSE), 0) -> 1 | AA11: =AND(X11=Y11, Y11=Z11) -> TRUE | AB11: =IFERROR(VLOOKUP($B11, aegis!$AF:$AG, 2, FALSE), 0) -> 0 | AC11: =IFERROR(VLOOKUP($B11, duel!$AF:$AG, 2, FALSE), 0) -> 0 | AD11: =IFERROR(VLOOKUP($B11, blitz!$AF:$AG, 2, FALSE), 0) -> 0 | AE11: =AND(AB11=AC11, AC11=AD11) -> TRUE | AF11: =IFERROR(VLOOKUP($B11, aegis!$AK:$AL, 2, FALSE), 0) -> 0 | AG11: =IFERROR(VLOOKUP($B11, duel!$AK:$AL, 2, FALSE), 0) -> 0 | AH11: =IFERROR(VLOOKUP($B11, blitz!$AK:$AL, 2, FALSE), 0) -> 0 | AI11: =AND(AF11=AG11, AG11=AH11) -> TRUE | AJ11: =IFERROR(VLOOKUP($B11, aegis!$AP:$AQ, 2, FALSE), 0) -> 1 | AK11: =IFERROR(VLOOKUP($B11, duel!$AP:$AQ, 2, FALSE), 0) -> 1 | AL11: =IFERROR(VLOOKUP($B11, blitz!$AP:$AQ, 2, FALSE), 0) -> 1 | AM11: =AND(AJ11=AK11, AK11=AL11) -> TRUE | AN11: =IFERROR(VLOOKUP($B11, aegis!$AU:$AV, 2, FALSE), 0) -> 0 | AO11: =IFERROR(VLOOKUP($B11, duel!$AU:$AV, 2, FALSE), 0) -> 0 | AP11: =IFERROR(VLOOKUP($B11, blitz!$AU:$AV, 2, FALSE), 0) -> 0 | AQ11: =AND(AN11=AO11, AO11=AP11) -> TRUE | AR11: =IFERROR(VLOOKUP($B11, aegis!$AZ:$BA, 2, FALSE), 0) -> 1 | AS11: =IFERROR(VLOOKUP($B11, duel!$AZ:$BA, 2, FALSE), 0) -> 1 | AT11: =IFERROR(VLOOKUP($B11, blitz!$AZ:$BA, 2, FALSE), 0) -> 1 | AU11: =AND(AR11=AS11, AS11=AT11) -> TRUE | AV11: =IFERROR(VLOOKUP($B11, aegis!$BE:$BF, 2, FALSE), 0) -> 0 | AW11: =IFERROR(VLOOKUP($B11, duel!$BE:$BF, 2, FALSE), 0) -> 0 | AX11: =IFERROR(VLOOKUP($B11, blitz!$BE:$BF, 2, FALSE), 0) -> 0 | AY11: =AND(AV11=AW11, AW11=AX11) -> TRUE | AZ11: =IFERROR(VLOOKUP($B11, aegis!$BJ:$BK, 2, FALSE), 0) -> 0 | BA11: =IFERROR(VLOOKUP($B11, duel!$BJ:$BK, 2, FALSE), 0) -> 0 | BB11: =IFERROR(VLOOKUP($B11, blitz!$BJ:$BK, 2, FALSE), 0) -> 0 | BC11: =AND(AZ11=BA11, BA11=BB11) -> TRUE | BD11: =IFERROR(VLOOKUP($B11, aegis!$BO:$BP, 2, FALSE), 0) -> 0 | BE11: =IFERROR(VLOOKUP($B11, duel!$BO:$BP, 2, FALSE), 0) -> 0 | BF11: =IFERROR(VLOOKUP($B11, blitz!$BO:$BP, 2, FALSE), 0) -> 0 | BG11: =AND(BD11=BE11, BE11=BF11) -> TRUE | BH11: =IFERROR(VLOOKUP($B11, aegis!$BT:$BU, 2, FALSE), 0) -> 0 | BI11: =IFERROR(VLOOKUP($B11, duel!$BT:$BU, 2, FALSE), 0) -> 0 | BJ11: =IFERROR(VLOOKUP($B11, blitz!$BT:$BU, 2, FALSE), 0) -> 0 | BK11: =AND(BH11=BI11, BI11=BJ11) -> TRUE | BL11: =IFERROR(VLOOKUP($B11, aegis!$BY:$BZ, 2, FALSE), 0) -> 0 | BM11: =IFERROR(VLOOKUP($B11, duel!$BY:$BZ, 2, FALSE), 0) -> 0 | BN11: =IFERROR(VLOOKUP($B11, blitz!$BY:$BZ, 2, FALSE), 0) -> 0 | BO11: =AND(BL11=BM11, BM11=BN11) -> TRUE | BP11: =IFERROR(VLOOKUP($B11, aegis!$CD:$CE, 2, FALSE), 0) -> 0 | BQ11: =IFERROR(VLOOKUP($B11, duel!$CD:$CE, 2, FALSE), 0) -> 0 | BR11: =IFERROR(VLOOKUP($B11, blitz!$CD:$CE, 2, FALSE), 0) -> 0 | BS11: =AND(BP11=BQ11, BQ11=BR11) -> TRUE | BT11: =IFERROR(VLOOKUP($B11, aegis!$CI:$CJ, 2, FALSE), 0) -> 0 | BU11: =IFERROR(VLOOKUP($B11, duel!$CI:$CJ, 2, FALSE), 0) -> 0 | BV11: =IFERROR(VLOOKUP($B11, blitz!$CI:$CJ, 2, FALSE), 0) -> 0 | BW11: =AND(BT11=BU11, BU11=BV11) -> TRUE | BX11: =IFERROR(VLOOKUP($B11, aegis!$CN:$CO, 2, FALSE), 0) -> 0 | BY11: =IFERROR(VLOOKUP($B11, duel!$CN:$CO, 2, FALSE), 0) -> 0 | BZ11: =IFERROR(VLOOKUP($B11, blitz!$CN:$CO, 2, FALSE), 0) -> 0 | CA11: =AND(BX11=BY11, BY11=BZ11) -> TRUE | CB11: =IFERROR(VLOOKUP($B11, aegis!$CS:$CT, 2, FALSE), 0) -> 0 | CC11: =IFERROR(VLOOKUP($B11, duel!$CS:$CT, 2, FALSE), 0) -> 0 | CD11: =IFERROR(VLOOKUP($B11, blitz!$CS:$CT, 2, FALSE), 0) -> 0 | CE11: =AND(CB11=CC11, CC11=CD11) -> TRUE | CF11: =IFERROR(VLOOKUP($B11, aegis!$CX:$CY, 2, FALSE), 0) -> 0 | CG11: =IFERROR(VLOOKUP($B11, duel!$CX:$CY, 2, FALSE), 0) -> 0 | CH11: =IFERROR(VLOOKUP($B11, blitz!$CX:$CY, 2, FALSE), 0) -> 0 | CI11: =AND(CF11=CG11, CG11=CH11) -> TRUE | CJ11: =IFERROR(VLOOKUP($B11, aegis!$DC:$DD, 2, FALSE), 0) -> 0 | CK11: =IFERROR(VLOOKUP($B11, duel!$DC:$DD, 2, FALSE), 0) -> 0 | CL11: =IFERROR(VLOOKUP($B11, blitz!$DC:$DD, 2, FALSE), 0) -> 0 | CM11: =AND(CJ11=CK11, CK11=CL11) -> TRUE | CN11: =IFERROR(VLOOKUP($B11, aegis!$DH:$DI, 2, FALSE), 0) -> 0 | CO11: =IFERROR(VLOOKUP($B11, duel!$DH:$DI, 2, FALSE), 0) -> 0 | CP11: =IFERROR(VLOOKUP($B11, blitz!$DH:$DI, 2, FALSE), 0) -> 0 | CQ11: =AND(CN11=CO11) -> TRUE | CR11: =IFERROR(VLOOKUP($B11, aegis!$DM:$DN, 2, FALSE), 0) -> 0 | CS11: =IFERROR(VLOOKUP($B11, duel!$DM:$DN, 2, FALSE), 0) -> 0 | CT11: =IFERROR(VLOOKUP($B11, blitz!$DM:$DN, 2, FALSE), 0) -> 0 | CU11: =AND(CR11=CS11, CS11=CT11) -> TRUE | CV11: =IFERROR(VLOOKUP($B11, aegis!$DR:$DS, 2, FALSE), 0) -> 0 | CW11: =IFERROR(VLOOKUP($B11, duel!$DR:$DS, 2, FALSE), 0) -> 0 | CX11: =IFERROR(VLOOKUP($B11, blitz!$DR:$DS, 2, FALSE), 0) -> 0 | CY11: =AND(CV11=CW11, CW11=CX11) -> TRUE
B12: 00000030 | C12: =AND(G12,K12,O12,S12,W12,AA12,AE12,AI12,AM12,AQ12,AU12,AY12,BC12,BG12,BK12,BO12,BS12,BW12,CA12,CE12,CI12,CM12,CQ12,CU12,CY12) -> TRUE | D12: =IFERROR(VLOOKUP($B12, aegis!$B:$C, 2, FALSE), 0) -> 0 | E12: =IFERROR(VLOOKUP($B12, duel!$B:$C, 2, FALSE), 0) -> 0 | F12: =IFERROR(VLOOKUP($B12, blitz!$B:$C, 2, FALSE), 0) -> 0 | G12: =AND(D12=E12, E12=F12) -> TRUE | H12: =IFERROR(VLOOKUP($B12, aegis!$G:$H, 2, FALSE), 0) -> 0 | I12: =IFERROR(VLOOKUP($B12, duel!$G:$H, 2, FALSE), 0) -> 0 | J12: =IFERROR(VLOOKUP($B12, blitz!$G:$H, 2, FALSE), 0) -> 0 | K12: =AND(H12=I12, I12=J12) -> TRUE | L12: =IFERROR(VLOOKUP($B12, aegis!$L:$M, 2, FALSE), 0) -> 24 | M12: =IFERROR(VLOOKUP($B12, duel!$L:$M, 2, FALSE), 0) -> 24 | N12: =IFERROR(VLOOKUP($B12, blitz!$L:$M, 2, FALSE), 0) -> 24 | O12: =AND(L12=M12, M12=N12) -> TRUE | P12: =IFERROR(VLOOKUP($B12, aegis!$Q:$R, 2, FALSE), 0) -> 14 | Q12: =IFERROR(VLOOKUP($B12, duel!$Q:$R, 2, FALSE), 0) -> 14 | R12: =IFERROR(VLOOKUP($B12, blitz!$Q:$R, 2, FALSE), 0) -> 14 | S12: =AND(P12=Q12, Q12=R12) -> TRUE | T12: =IFERROR(VLOOKUP($B12, aegis!$V:$W, 2, FALSE), 0) -> 3 | U12: =IFERROR(VLOOKUP($B12, duel!$V:$W, 2, FALSE), 0) -> 3 | V12: =IFERROR(VLOOKUP($B12, blitz!$V:$W, 2, FALSE), 0) -> 3 | W12: =AND(T12=U12, U12=V12) -> TRUE | X12: =IFERROR(VLOOKUP($B12, aegis!$AA:$AB, 2, FALSE), 0) -> 2 | Y12: =IFERROR(VLOOKUP($B12, duel!$AA:$AB, 2, FALSE), 0) -> 2 | Z12: =IFERROR(VLOOKUP($B12, blitz!$AA:$AB, 2, FALSE), 0) -> 2 | AA12: =AND(X12=Y12, Y12=Z12) -> TRUE | AB12: =IFERROR(VLOOKUP($B12, aegis!$AF:$AG, 2, FALSE), 0) -> 3 | AC12: =IFERROR(VLOOKUP($B12, duel!$AF:$AG, 2, FALSE), 0) -> 3 | AD12: =IFERROR(VLOOKUP($B12, blitz!$AF:$AG, 2, FALSE), 0) -> 3 | AE12: =AND(AB12=AC12, AC12=AD12) -> TRUE | AF12: =IFERROR(VLOOKUP($B12, aegis!$AK:$AL, 2, FALSE), 0) -> 0 | AG12: =IFERROR(VLOOKUP($B12, duel!$AK:$AL, 2, FALSE), 0) -> 0 | AH12: =IFERROR(VLOOKUP($B12, blitz!$AK:$AL, 2, FALSE), 0) -> 0 | AI12: =AND(AF12=AG12, AG12=AH12) -> TRUE | AJ12: =IFERROR(VLOOKUP($B12, aegis!$AP:$AQ, 2, FALSE), 0) -> 3 | AK12: =IFERROR(VLOOKUP($B12, duel!$AP:$AQ, 2, FALSE), 0) -> 3 | AL12: =IFERROR(VLOOKUP($B12, blitz!$AP:$AQ, 2, FALSE), 0) -> 3 | AM12: =AND(AJ12=AK12, AK12=AL12) -> TRUE | AN12: =IFERROR(VLOOKUP($B12, aegis!$AU:$AV, 2, FALSE), 0) -> 1 | AO12: =IFERROR(VLOOKUP($B12, duel!$AU:$AV, 2, FALSE), 0) -> 1 | AP12: =IFERROR(VLOOKUP($B12, blitz!$AU:$AV, 2, FALSE), 0) -> 1 | AQ12: =AND(AN12=AO12, AO12=AP12) -> TRUE | AR12: =IFERROR(VLOOKUP($B12, aegis!$AZ:$BA, 2, FALSE), 0) -> 2 | AS12: =IFERROR(VLOOKUP($B12, duel!$AZ:$BA, 2, FALSE), 0) -> 2 | AT12: =IFERROR(VLOOKUP($B12, blitz!$AZ:$BA, 2, FALSE), 0) -> 2 | AU12: =AND(AR12=AS12, AS12=AT12) -> TRUE | AV12: =IFERROR(VLOOKUP($B12, aegis!$BE:$BF, 2, FALSE), 0) -> 2 | AW12: =IFERROR(VLOOKUP($B12, duel!$BE:$BF, 2, FALSE), 0) -> 2 | AX12: =IFERROR(VLOOKUP($B12, blitz!$BE:$BF, 2, FALSE), 0) -> 2 | AY12: =AND(AV12=AW12, AW12=AX12) -> TRUE | AZ12: =IFERROR(VLOOKUP($B12, aegis!$BJ:$BK, 2, FALSE), 0) -> 0 | BA12: =IFERROR(VLOOKUP($B12, duel!$BJ:$BK, 2, FALSE), 0) -> 0 | BB12: =IFERROR(VLOOKUP($B12, blitz!$BJ:$BK, 2, FALSE), 0) -> 0 | BC12: =AND(AZ12=BA12, BA12=BB12) -> TRUE | BD12: =IFERROR(VLOOKUP($B12, aegis!$BO:$BP, 2, FALSE), 0) -> 0 | BE12: =IFERROR(VLOOKUP($B12, duel!$BO:$BP, 2, FALSE), 0) -> 0 | BF12: =IFERROR(VLOOKUP($B12, blitz!$BO:$BP, 2, FALSE), 0) -> 0 | BG12: =AND(BD12=BE12, BE12=BF12) -> TRUE | BH12: =IFERROR(VLOOKUP($B12, aegis!$BT:$BU, 2, FALSE), 0) -> 0 | BI12: =IFERROR(VLOOKUP($B12, duel!$BT:$BU, 2, FALSE), 0) -> 0 | BJ12: =IFERROR(VLOOKUP($B12, blitz!$BT:$BU, 2, FALSE), 0) -> 0 | BK12: =AND(BH12=BI12, BI12=BJ12) -> TRUE | BL12: =IFERROR(VLOOKUP($B12, aegis!$BY:$BZ, 2, FALSE), 0) -> 2 | BM12: =IFERROR(VLOOKUP($B12, duel!$BY:$BZ, 2, FALSE), 0) -> 2 | BN12: =IFERROR(VLOOKUP($B12, blitz!$BY:$BZ, 2, FALSE), 0) -> 2 | BO12: =AND(BL12=BM12, BM12=BN12) -> TRUE | BP12: =IFERROR(VLOOKUP($B12, aegis!$CD:$CE, 2, FALSE), 0) -> 0 | BQ12: =IFERROR(VLOOKUP($B12, duel!$CD:$CE, 2, FALSE), 0) -> 0 | BR12: =IFERROR(VLOOKUP($B12, blitz!$CD:$CE, 2, FALSE), 0) -> 0 | BS12: =AND(BP12=BQ12, BQ12=BR12) -> TRUE | BT12: =IFERROR(VLOOKUP($B12, aegis!$CI:$CJ, 2, FALSE), 0) -> 6 | BU12: =IFERROR(VLOOKUP($B12, duel!$CI:$CJ, 2, FALSE), 0) -> 6 | BV12: =IFERROR(VLOOKUP($B12, blitz!$CI:$CJ, 2, FALSE), 0) -> 6 | BW12: =AND(BT12=BU12, BU12=BV12) -> TRUE | BX12: =IFERROR(VLOOKUP($B12, aegis!$CN:$CO, 2, FALSE), 0) -> 6 | BY12: =IFERROR(VLOOKUP($B12, duel!$CN:$CO, 2, FALSE), 0) -> 6 | BZ12: =IFERROR(VLOOKUP($B12, blitz!$CN:$CO, 2, FALSE), 0) -> 6 | CA12: =AND(BX12=BY12, BY12=BZ12) -> TRUE | CB12: =IFERROR(VLOOKUP($B12, aegis!$CS:$CT, 2, FALSE), 0) -> 33 | CC12: =IFERROR(VLOOKUP($B12, duel!$CS:$CT, 2, FALSE), 0) -> 33 | CD12: =IFERROR(VLOOKUP($B12, blitz!$CS:$CT, 2, FALSE), 0) -> 33 | CE12: =AND(CB12=CC12, CC12=CD12) -> TRUE | CF12: =IFERROR(VLOOKUP($B12, aegis!$CX:$CY, 2, FALSE), 0) -> 0 | CG12: =IFERROR(VLOOKUP($B12, duel!$CX:$CY, 2, FALSE), 0) -> 0 | CH12: =IFERROR(VLOOKUP($B12, blitz!$CX:$CY, 2, FALSE), 0) -> 0 | CI12: =AND(CF12=CG12, CG12=CH12) -> TRUE | CJ12: =IFERROR(VLOOKUP($B12, aegis!$DC:$DD, 2, FALSE), 0) -> 0 | CK12: =IFERROR(VLOOKUP($B12, duel!$DC:$DD, 2, FALSE), 0) -> 0 | CL12: =IFERROR(VLOOKUP($B12, blitz!$DC:$DD, 2, FALSE), 0) -> 0 | CM12: =AND(CJ12=CK12, CK12=CL12) -> TRUE | CN12: =IFERROR(VLOOKUP($B12, aegis!$DH:$DI, 2, FALSE), 0) -> 2 | CO12: =IFERROR(VLOOKUP($B12, duel!$DH:$DI, 2, FALSE), 0) -> 2 | CP12: =IFERROR(VLOOKUP($B12, blitz!$DH:$DI, 2, FALSE), 0) -> 0 | CQ12: =AND(CN12=CO12) -> TRUE | CR12: =IFERROR(VLOOKUP($B12, aegis!$DM:$DN, 2, FALSE), 0) -> 3 | CS12: =IFERROR(VLOOKUP($B12, duel!$DM:$DN, 2, FALSE), 0) -> 3 | CT12: =IFERROR(VLOOKUP($B12, blitz!$DM:$DN, 2, FALSE), 0) -> 3 | CU12: =AND(CR12=CS12, CS12=CT12) -> TRUE | CV12: =IFERROR(VLOOKUP($B12, aegis!$DR:$DS, 2, FALSE), 0) -> 3 | CW12: =IFERROR(VLOOKUP($B12, duel!$DR:$DS, 2, FALSE), 0) -> 3 | CX12: =IFERROR(VLOOKUP($B12, blitz!$DR:$DS, 2, FALSE), 0) -> 3 | CY12: =AND(CV12=CW12, CW12=CX12) -> TRUE
A13: ○ | B13: 02000001 | C13: =AND(G13,K13,O13,S13,W13,AA13,AE13,AI13,AM13,AQ13,AU13,AY13,BC13,BG13,BK13,BO13,BS13,BW13,CA13,CE13,CI13,CM13,CQ13,CU13,CY13) -> FALSE | D13: =IFERROR(VLOOKUP($B13, aegis!$B:$C, 2, FALSE), 0) -> 180 | E13: =IFERROR(VLOOKUP($B13, duel!$B:$C, 2, FALSE), 0) -> 180 | F13: =IFERROR(VLOOKUP($B13, blitz!$B:$C, 2, FALSE), 0) -> 180 | G13: =AND(D13=E13, E13=F13) -> TRUE | H13: =IFERROR(VLOOKUP($B13, aegis!$G:$H, 2, FALSE), 0) -> 105 | I13: =IFERROR(VLOOKUP($B13, duel!$G:$H, 2, FALSE), 0) -> 105 | J13: =IFERROR(VLOOKUP($B13, blitz!$G:$H, 2, FALSE), 0) -> 105 | K13: =AND(H13=I13, I13=J13) -> TRUE | L13: =IFERROR(VLOOKUP($B13, aegis!$L:$M, 2, FALSE), 0) -> 252 | M13: =IFERROR(VLOOKUP($B13, duel!$L:$M, 2, FALSE), 0) -> 252 | N13: =IFERROR(VLOOKUP($B13, blitz!$L:$M, 2, FALSE), 0) -> 252 | O13: =AND(L13=M13, M13=N13) -> TRUE | P13: =IFERROR(VLOOKUP($B13, aegis!$Q:$R, 2, FALSE), 0) -> 147 | Q13: =IFERROR(VLOOKUP($B13, duel!$Q:$R, 2, FALSE), 0) -> 147 | R13: =IFERROR(VLOOKUP($B13, blitz!$Q:$R, 2, FALSE), 0) -> 147 | S13: =AND(P13=Q13, Q13=R13) -> TRUE | T13: =IFERROR(VLOOKUP($B13, aegis!$V:$W, 2, FALSE), 0) -> 1040 | U13: =IFERROR(VLOOKUP($B13, duel!$V:$W, 2, FALSE), 0) -> 1040 | V13: =IFERROR(VLOOKUP($B13, blitz!$V:$W, 2, FALSE), 0) -> 1040 | W13: =AND(T13=U13, U13=V13) -> TRUE | X13: =IFERROR(VLOOKUP($B13, aegis!$AA:$AB, 2, FALSE), 0) -> 7 | Y13: =IFERROR(VLOOKUP($B13, duel!$AA:$AB, 2, FALSE), 0) -> 11 | Z13: =IFERROR(VLOOKUP($B13, blitz!$AA:$AB, 2, FALSE), 0) -> 7 | AA13: =AND(X13=Y13, Y13=Z13) -> FALSE | AB13: =IFERROR(VLOOKUP($B13, aegis!$AF:$AG, 2, FALSE), 0) -> 309 | AC13: =IFERROR(VLOOKUP($B13, duel!$AF:$AG, 2, FALSE), 0) -> 309 | AD13: =IFERROR(VLOOKUP($B13, blitz!$AF:$AG, 2, FALSE), 0) -> 309 | AE13: =AND(AB13=AC13, AC13=AD13) -> TRUE | AF13: =IFERROR(VLOOKUP($B13, aegis!$AK:$AL, 2, FALSE), 0) -> 5 | AG13: =IFERROR(VLOOKUP($B13, duel!$AK:$AL, 2, FALSE), 0) -> 1 | AH13: =IFERROR(VLOOKUP($B13, blitz!$AK:$AL, 2, FALSE), 0) -> 1 | AI13: =AND(AF13=AG13, AG13=AH13) -> FALSE | AJ13: =IFERROR(VLOOKUP($B13, aegis!$AP:$AQ, 2, FALSE), 0) -> 25 | AK13: =IFERROR(VLOOKUP($B13, duel!$AP:$AQ, 2, FALSE), 0) -> 25 | AL13: =IFERROR(VLOOKUP($B13, blitz!$AP:$AQ, 2, FALSE), 0) -> 25 | AM13: =AND(AJ13=AK13, AK13=AL13) -> TRUE | AN13: =IFERROR(VLOOKUP($B13, aegis!$AU:$AV, 2, FALSE), 0) -> 17 | AO13: =IFERROR(VLOOKUP($B13, duel!$AU:$AV, 2, FALSE), 0) -> 17 | AP13: =IFERROR(VLOOKUP($B13, blitz!$AU:$AV, 2, FALSE), 0) -> 17 | AQ13: =AND(AN13=AO13, AO13=AP13) -> TRUE | AR13: =IFERROR(VLOOKUP($B13, aegis!$AZ:$BA, 2, FALSE), 0) -> 4 | AS13: =IFERROR(VLOOKUP($B13, duel!$AZ:$BA, 2, FALSE), 0) -> 4 | AT13: =IFERROR(VLOOKUP($B13, blitz!$AZ:$BA, 2, FALSE), 0) -> 4 | AU13: =AND(AR13=AS13, AS13=AT13) -> TRUE | AV13: =IFERROR(VLOOKUP($B13, aegis!$BE:$BF, 2, FALSE), 0) -> 15 | AW13: =IFERROR(VLOOKUP($B13, duel!$BE:$BF, 2, FALSE), 0) -> 15 | AX13: =IFERROR(VLOOKUP($B13, blitz!$BE:$BF, 2, FALSE), 0) -> 15 | AY13: =AND(AV13=AW13, AW13=AX13) -> TRUE | AZ13: =IFERROR(VLOOKUP($B13, aegis!$BJ:$BK, 2, FALSE), 0) -> 1 | BA13: =IFERROR(VLOOKUP($B13, duel!$BJ:$BK, 2, FALSE), 0) -> 1 | BB13: =IFERROR(VLOOKUP($B13, blitz!$BJ:$BK, 2, FALSE), 0) -> 1 | BC13: =AND(AZ13=BA13, BA13=BB13) -> TRUE | BD13: =IFERROR(VLOOKUP($B13, aegis!$BO:$BP, 2, FALSE), 0) -> 0 | BE13: =IFERROR(VLOOKUP($B13, duel!$BO:$BP, 2, FALSE), 0) -> 0 | BF13: =IFERROR(VLOOKUP($B13, blitz!$BO:$BP, 2, FALSE), 0) -> 0 | BG13: =AND(BD13=BE13, BE13=BF13) -> TRUE | BH13: =IFERROR(VLOOKUP($B13, aegis!$BT:$BU, 2, FALSE), 0) -> 97 | BI13: =IFERROR(VLOOKUP($B13, duel!$BT:$BU, 2, FALSE), 0) -> 97 | BJ13: =IFERROR(VLOOKUP($B13, blitz!$BT:$BU, 2, FALSE), 0) -> 97 | BK13: =AND(BH13=BI13, BI13=BJ13) -> TRUE | BL13: =IFERROR(VLOOKUP($B13, aegis!$BY:$BZ, 2, FALSE), 0) -> 12 | BM13: =IFERROR(VLOOKUP($B13, duel!$BY:$BZ, 2, FALSE), 0) -> 12 | BN13: =IFERROR(VLOOKUP($B13, blitz!$BY:$BZ, 2, FALSE), 0) -> 12 | BO13: =AND(BL13=BM13, BM13=BN13) -> TRUE | BP13: =IFERROR(VLOOKUP($B13, aegis!$CD:$CE, 2, FALSE), 0) -> 15 | BQ13: =IFERROR(VLOOKUP($B13, duel!$CD:$CE, 2, FALSE), 0) -> 15 | BR13: =IFERROR(VLOOKUP($B13, blitz!$CD:$CE, 2, FALSE), 0) -> 15 | BS13: =AND(BP13=BQ13, BQ13=BR13) -> TRUE | BT13: =IFERROR(VLOOKUP($B13, aegis!$CI:$CJ, 2, FALSE), 0) -> 54 | BU13: =IFERROR(VLOOKUP($B13, duel!$CI:$CJ, 2, FALSE), 0) -> 54 | BV13: =IFERROR(VLOOKUP($B13, blitz!$CI:$CJ, 2, FALSE), 0) -> 54 | BW13: =AND(BT13=BU13, BU13=BV13) -> TRUE | BX13: =IFERROR(VLOOKUP($B13, aegis!$CN:$CO, 2, FALSE), 0) -> 54 | BY13: =IFERROR(VLOOKUP($B13, duel!$CN:$CO, 2, FALSE), 0) -> 54 | BZ13: =IFERROR(VLOOKUP($B13, blitz!$CN:$CO, 2, FALSE), 0) -> 54 | CA13: =AND(BX13=BY13, BY13=BZ13) -> TRUE | CB13: =IFERROR(VLOOKUP($B13, aegis!$CS:$CT, 2, FALSE), 0) -> 250 | CC13: =IFERROR(VLOOKUP($B13, duel!$CS:$CT, 2, FALSE), 0) -> 250 | CD13: =IFERROR(VLOOKUP($B13, blitz!$CS:$CT, 2, FALSE), 0) -> 250 | CE13: =AND(CB13=CC13, CC13=CD13) -> TRUE | CF13: =IFERROR(VLOOKUP($B13, aegis!$CX:$CY, 2, FALSE), 0) -> 1376 | CG13: =IFERROR(VLOOKUP($B13, duel!$CX:$CY, 2, FALSE), 0) -> 1376 | CH13: =IFERROR(VLOOKUP($B13, blitz!$CX:$CY, 2, FALSE), 0) -> 150 | CI13: =AND(CF13=CG13, CG13=CH13) -> FALSE | CJ13: =IFERROR(VLOOKUP($B13, aegis!$DC:$DD, 2, FALSE), 0) -> 3 | CK13: =IFERROR(VLOOKUP($B13, duel!$DC:$DD, 2, FALSE), 0) -> 3 | CL13: =IFERROR(VLOOKUP($B13, blitz!$DC:$DD, 2, FALSE), 0) -> 3 | CM13: =AND(CJ13=CK13, CK13=CL13) -> TRUE | CN13: =IFERROR(VLOOKUP($B13, aegis!$DH:$DI, 2, FALSE), 0) -> 14 | CO13: =IFERROR(VLOOKUP($B13, duel!$DH:$DI, 2, FALSE), 0) -> 14 | CP13: =IFERROR(VLOOKUP($B13, blitz!$DH:$DI, 2, FALSE), 0) -> 0 | CQ13: =AND(CN13=CO13) -> TRUE | CR13: =IFERROR(VLOOKUP($B13, aegis!$DM:$DN, 2, FALSE), 0) -> 18 | CS13: =IFERROR(VLOOKUP($B13, duel!$DM:$DN, 2, FALSE), 0) -> 18 | CT13: =IFERROR(VLOOKUP($B13, blitz!$DM:$DN, 2, FALSE), 0) -> 18 | CU13: =AND(CR13=CS13, CS13=CT13) -> TRUE | CV13: =IFERROR(VLOOKUP($B13, aegis!$DR:$DS, 2, FALSE), 0) -> 309 | CW13: =IFERROR(VLOOKUP($B13, duel!$DR:$DS, 2, FALSE), 0) -> 309 | CX13: =IFERROR(VLOOKUP($B13, blitz!$DR:$DS, 2, FALSE), 0) -> 309 | CY13: =AND(CV13=CW13, CW13=CX13) -> TRUE
